Workbook

Sheet Item codes
A1: S.NO | B1: ITEM CODE | C1: ITEM DESC
A2: 1 | B2: RTHTMTBNET72X33X06 | C2: Peps Restonic Hotel Motel Bonnell Euro Top 72X33X06 | Q2: RTHTMTPKET72X30X06 | R2: Peps Restonic Hotel Motel Pocketed Euro Top 72X30X06 | S2: RTHTMTPKET72X30X08 | T2: Peps Restonic Hotel Motel Pocketed Euro Top 72X30X08 | U2: RTHTMTPKET72X30X10 | V2: Peps Restonic Hotel Motel Pocketed Euro Top 72X30X10 | W2: RTHTMTPKMFET72X30X06 | X2: Peps Restonic Hotel Motel Pocketed Memory Foam Euro Top 72X30X06 | Y2: RTHTMTPKMFET72X30X08 | Z2: Peps Restonic Hotel Motel Pocketed Memory Foam Euro Top 72X30X08 | AA2: RTHTMTPKMFET72X30X10 | AB2: Peps Restonic Hotel Motel Pocketed Memory Foam Euro Top 72X30X10 | AC2: RTHTMTPKMFRG72X30X06 | AD2: Peps Restonic Hotel Motel Pocketed Memory Foam Regular 72X30X06 | AE2: RTHTMTPKMFRG72X30X08 | AF2: Peps Restonic Hotel Motel Pocketed Memory Foam Regular 72X30X08 | AG2: RTHTMTPKMFRG72X30X10 | AH2: Peps Restonic Hotel Motel Pocketed Memory Foam Regular 72X30X10 | AI2: RTHTMTPKMFRG72X30X12 | AJ2: Peps Restonic Hotel Motel Pocketed Memory Foam Regular 72X30X12 | AK2: RTHTMTPKPT72X30X06 | AL2: Peps Restonic Hotel Motel Pocketed Pillow Top 72X30X06 | AM2: RTHTMTPKPT72X30X08 | AN2: Peps Restonic Hotel Motel Pocketed Pillow Top 72X30X08 | AO2: RTHTMTPKPT72X30X10 | AP2: Peps Restonic Hotel Motel Pocketed Pillow Top 72X30X10 | AQ2: RTHTMTPKRG72X30X06 | AR2: Peps Restonic Hotel Motel Pocketed Regular 72X30X06 | AS2: RTHTMTPKRG72X30X08 | AT2: Peps Restonic Hotel Motel Pocketed Regular 72X30X08 | AU2: RTHTMTPKRG72X30X10 | AV2: Peps Restonic Hotel Motel Pocketed Regular 72X30X10 | AW2: RTHTMTPKRG72X30X12 | AX2: Peps Restonic Hotel Motel Pocketed Regular 72X30X12
A3: 2 | B3: RTHTMTBNET72X39X06 | C3: Peps Restonic Hotel Motel Bonnell Euro Top 72X39X06
A4: 3 | B4: RTHTMTBNET72X45X06 | C4: Peps Restonic Hotel Motel Bonnell Euro Top 72X45X06
A5: 4 | B5: RTHTMTBNET72X51X06 | C5: Peps Restonic Hotel Motel Bonnell Euro Top 72X51X06
A6: 5 | B6: RTHTMTBNET72X54X06 | C6: Peps Restonic Hotel Motel Bonnell Euro Top 72X54X06
A7: 6 | B7: RTHTMTBNET72X57X06 | C7: Peps Restonic Hotel Motel Bonnell Euro Top 72X57X06
A8: 7 | B8: RTHTMTBNET72X63X06 | C8: Peps Restonic Hotel Motel Bonnell Euro Top 72X63X06
A9: 8 | B9: RTHTMTBNET72X69X06 | C9: Peps Restonic Hotel Motel Bonnell Euro Top 72X69X06
A10: 9 | B10: RTHTMTBNET75X33X06 | C10: Peps Restonic Hotel Motel Bonnell Euro Top 75X33X06
A11: 10 | B11: RTHTMTBNET75X39X06 | C11: Peps Restonic Hotel Motel Bonnell Euro Top 75X39X06
A12: 11 | B12: RTHTMTBNET75X45X06 | C12: Peps Restonic Hotel Motel Bonnell Euro Top 75X45X06
A13: 12 | B13: RTHTMTBNET75X51X06 | C13: Peps Restonic Hotel Motel Bonnell Euro Top 75X51X06
A14: 13 | B14: RTHTMTBNET75X54X06 | C14: Peps Restonic Hotel Motel Bonnell Euro Top 75X54X06
... A1361: 1360 | B1361: RTHTMTPKRG84X69X12 | C1361: Peps Restonic Hotel Motel Pocketed Regular 84X69X12

Sheet Workings
A1: DOIGH | B1: S.no | C1: R.no | D1: Date | E1: Bom Code/PS.No | F1: PS Desc. | G1: Item | H1: PS Desc. | I1: PS Usage | J1: PS Category | K1: Process Plan | L1: Uom | M1: Qty | N1: Default For | O1: Wh Code | P1: PS Seq | Q1: I/O Flag | R1: Issue Item | S1: Item Desc | T1: Uom | U1: Qty | V1: Std Wh Code | W1: Backflush | X1: Status | Y1: CC | Z1: LENGTH | AA1: WIDTH | AB1: HE | AC1: Length | AD1: width | AE1: condition | AG1: Conv | AH1: rate | AI1: sub.tot | AJ1: tot | AK1: round | AL1: rm-rate | AM1: PRO-RATE | AN1: Wastage | AO1: DL | AP1: MOH | AQ1: Dep | AR1: Standard Cost | AS1: R-UP | AT1: RM-COST | AU1: PRO-RATE
A2: 1 | B2: 1 | C2: 1 | D2: 28.03.2024 | E2: SFG-FRBNET-MEM-BOR-72X33X08 | F2: Restonic Hotel Motel Bonnell Euro Top Memory Border 72X33X08 | G2: =E2 -> SFG-FRBNET-MEM-BOR-72X33X08 | H2: =F2 -> Restonic Hotel Motel Bonnell Euro Top Memory Border 72X33X08 | I2: Standard | J2: Production | K2: TAIL-BORDER | L2: NOS | M2: 1 | N2: MRP&Rollup | O2: CBESFG | P2: 10 | Q2: I | R2: RM-THRD-QS-TKT40 | S2: THREAD TKT40 210D/3 PLY 10000MTS | T2: MTR | U2: 5.6 | V2: CBEWIP | W2: Backflush | X2: Active | Y2: =RIGHT(E2,8) -> 72X33X08 | Z2: =LEFT(Y2,2) -> 72 | AA2: =MID(Y2,4,2) -> 33 | AB2: =RIGHT(Y2,2) -> 08 | AC2: =Z2 -> 72 | AD2: =AA2 -> 33 | AG2: =U2/10000 -> 0.00056 | AH2: =VLOOKUP(R2,'Rm-feb-24'!B:P,15,0) -> 231.1423 | AI2: =AG2*AH2 -> 0.12943969 | AJ2: =SUM(AI2:AI9) -> 144.14764 | AK2: =ROUND(AJ2,3) -> 144.148 | AL2: =AK2 -> 144.148 | AM2: =+AL2+AR2 -> 161.98617 | AN2: =+SUM(((AL2*3%*18%))) -> 0.7783992 | AO2: =+SUM(((AL2*14.33%*53%))) -> 10.947896 | AP2: =+SUM(((AL2*5.92%*53%))) -> 4.5227876 | AQ2: =+SUM(((AL2*2.08%*53%))) -> 1.5890876 | AR2: =SUM(AN2:AQ2) -> 17.838171 | AS2: =ROUNDUP(AM2,0) -> 162 | AT2: =AL2 -> 144.148 | AU2: =AS2 -> 162
A3: 2 | B3: 2 | C3: =C2 -> 1 | D3: =D2 -> 28.03.2024 | E3: =E2 -> SFG-FRBNET-MEM-BOR-72X33X08 | F3: =F2 -> Restonic Hotel Motel Bonnell Euro Top Memory Border 72X33X08 | G3: =G2 -> SFG-FRBNET-MEM-BOR-72X33X08 | H3: =H2 -> Restonic Hotel Motel Bonnell Euro Top Memory Border 72X33X08 | I3: Standard | J3: Production | K3: TAIL-BORDER | L3: NOS | M3: 1 | N3: MRP&Rollup | O3: CBESFG | P3: 20 | Q3: I | R3: HW-CTON-THREAD | S3: COTTON THREAD WHITE 3PLY | T3: MTR | U3: 5 | V3: CBEWIP | W3: Backflush | X3: Active | Y3: =RIGHT(E3,8) -> 72X33X08 | Z3: =LEFT(Y3,2) -> 72 | AA3: =MID(Y3,4,2) -> 33 | AB3: =RIGHT(Y3,2) -> 08 | AC3: =AC2 -> 72 | AD3: =AD2 -> 33 | AG3: =U3/5000 -> 0.001 | AH3: =VLOOKUP(R3,'Rm-feb-24'!B:P,15,0) -> 58 | AI3: =AG3*AH3 -> 0.058 | AT3: =AT2 -> 144.148 | AU3: =AU2 -> 162
A4: 3 | B4: 3 | C4: =C3 -> 1 | D4: =D3 -> 28.03.2024 | E4: =E3 -> SFG-FRBNET-MEM-BOR-72X33X08 | F4: =F3 -> Restonic Hotel Motel Bonnell Euro Top Memory Border 72X33X08 | G4: =G3 -> SFG-FRBNET-MEM-BOR-72X33X08 | H4: =H3 -> Restonic Hotel Motel Bonnell Euro Top Memory Border 72X33X08 | I4: Standard | J4: Production | K4: TAIL-BORDER | L4: NOS | M4: 1 | N4: MRP&Rollup | O4: CBESFG | P4: 30 | Q4: I | R4: SFG-RTHTMT-BNPK-MEM-BOR-21CM | S4: Hotel Motel Poc ET-8 8MM/16D Pre Foam Memory Border 21 CM Height | T4: MTR | U4: =AE4 -> 5.411 | V4: CBESFG | W4: Backflush | X4: Active | Y4: =RIGHT(E4,8) -> 72X33X08 | Z4: =LEFT(Y4,2) -> 72 | AA4: =MID(Y4,4,2) -> 33 | AB4: =RIGHT(Y4,2) -> 08 | AC4: =AC3 -> 72 | AD4: =AD3 -> 33 | AE4: =ROUNDUP(((((AC4+AD4)*2)+3)*0.0254),3) -> 5.411 | AG4: =U4 -> 5.411 | AH4: =VLOOKUP(R4,'SFG-RM'!A:B,2,0) -> 21.475377 | AI4: =AG4*AH4 -> 116.20327 | AT4: =AT3 -> 144.148 | AU4: =AU3 -> 162
A5: 4 | B5: 4 | C5: =C4 -> 1 | D5: =D4 -> 28.03.2024 | E5: =E4 -> SFG-FRBNET-MEM-BOR-72X33X08 | F5: =F4 -> Restonic Hotel Motel Bonnell Euro Top Memory Border 72X33X08 | G5: =G4 -> SFG-FRBNET-MEM-BOR-72X33X08 | H5: =H4 -> Restonic Hotel Motel Bonnell Euro Top Memory Border 72X33X08 | I5: Standard | J5: Production | K5: TAIL-BORDER | L5: NOS | M5: 1 | N5: MRP&Rollup | O5: CBESFG | P5: 40 | Q5: I | R5: RMI-HCC-SDE-LBL | S5: HOTEL COMFORT CARE SIDE LABEL (IMPORT) | T5: NOS | U5: 1 | V5: CBEWIP | W5: Backflush | X5: Active | Y5: =RIGHT(E5,8) -> 72X33X08 | Z5: =LEFT(Y5,2) -> 72 | AA5: =MID(Y5,4,2) -> 33 | AB5: =RIGHT(Y5,2) -> 08 | AC5: =AC4 -> 72 | AD5: =AD4 -> 33 | AE5: =ROUNDUP(((((72+30)*2)+3)*0.0254),3) -> 5.258 | AG5: =U5 -> 1 | AH5: =VLOOKUP(R5,'Rm-feb-24'!B:P,15,0) -> 5.9957 | AI5: =AG5*AH5 -> 5.9957 | AT5: =AT4 -> 144.148 | AU5: =AU4 -> 162
A6: 5 | B6: 5 | C6: =C5 -> 1 | D6: =D5 -> 28.03.2024 | E6: =E5 -> SFG-FRBNET-MEM-BOR-72X33X08 | F6: =F5 -> Restonic Hotel Motel Bonnell Euro Top Memory Border 72X33X08 | G6: =G5 -> SFG-FRBNET-MEM-BOR-72X33X08 | H6: =H5 -> Restonic Hotel Motel Bonnell Euro Top Memory Border 72X33X08 | I6: Standard | J6: Production | K6: TAIL-BORDER | L6: NOS | M6: 1 | N6: MRP&Rollup | O6: CBESFG | P6: 50 | Q6: I | R6: RML-MRP-BACK-LBL | S6: MRP BACK LABEL(PLAIN) | T6: NOS | U6: 1 | V6: CBEWIP | W6: Backflush | X6: Active | Y6: =RIGHT(E6,8) -> 72X33X08 | Z6: =LEFT(Y6,2) -> 72 | AA6: =MID(Y6,4,2) -> 33 | AB6: =RIGHT(Y6,2) -> 08 | AC6: =AC5 -> 72 | AD6: =AD5 -> 33 | AG6: =U6 -> 1 | AH6: =VLOOKUP(R6,'Rm-feb-24'!B:P,15,0) -> 1.3275 | AI6: =AG6*AH6 -> 1.3275 | AT6: =AT5 -> 144.148 | AU6: =AU5 -> 162
A7: 6 | B7: 6 | C7: =C6 -> 1 | D7: =D6 -> 28.03.2024 | E7: =E6 -> SFG-FRBNET-MEM-BOR-72X33X08 | F7: =F6 -> Restonic Hotel Motel Bonnell Euro Top Memory Border 72X33X08 | G7: =G6 -> SFG-FRBNET-MEM-BOR-72X33X08 | H7: =H6 -> Restonic Hotel Motel Bonnell Euro Top Memory Border 72X33X08 | I7: Standard | J7: Production | K7: TAIL-BORDER | L7: NOS | M7: 1 | N7: MRP&Rollup | O7: CBESFG | P7: 60 | Q7: I | R7: RML-DRN-LBL | S7: DIRECTION LABEL | T7: NOS | U7: 1 | V7: CBEWIP | W7: Backflush | X7: Active | Y7: =RIGHT(E7,8) -> 72X33X08 | Z7: =LEFT(Y7,2) -> 72 | AA7: =MID(Y7,4,2) -> 33 | AB7: =RIGHT(Y7,2) -> 08 | AC7: =AC6 -> 72 | AD7: =AD6 -> 33 | AG7: =U7 -> 1 | AH7: =VLOOKUP(R7,'Rm-feb-24'!B:P,15,0) -> 1.7318 | AI7: =AG7*AH7 -> 1.7318 | AT7: =AT6 -> 144.148 | AU7: =AU6 -> 162
A8: 7 | B8: 7 | C8: =C7 -> 1 | D8: =D7 -> 28.03.2024 | E8: =E7 -> SFG-FRBNET-MEM-BOR-72X33X08 | F8: =F7 -> Restonic Hotel Motel Bonnell Euro Top Memory Border 72X33X08 | G8: =G7 -> SFG-FRBNET-MEM-BOR-72X33X08 | H8: =H7 -> Restonic Hotel Motel Bonnell Euro Top Memory Border 72X33X08 | I8: Standard | J8: Production | K8: TAIL-BORDER | L8: NOS | M8: 1 | N8: MRP&Rollup | O8: CBESFG | P8: 70 | Q8: I | R8: SFG-RTHTMT-MEM-HANDLE | S8: Restonic Hotel Motel Memory Handle | T8: MTR | U8: 0.64 | V8: CBESFG | W8: Backflush | X8: Active | Y8: =RIGHT(E8,8) -> 72X33X08 | Z8: =LEFT(Y8,2) -> 72 | AA8: =MID(Y8,4,2) -> 33 | AB8: =RIGHT(Y8,2) -> 08 | AC8: =AC7 -> 72 | AD8: =AD7 -> 33 | AG8: =U8 -> 0.64 | AH8: =VLOOKUP(R8,'SFG-RM'!A:B,2,0) -> 14.621455 | AI8: =AG8*AH8 -> 9.3577314 | AT8: =AT7 -> 144.148 | AU8: =AU7 -> 162
A9: 8 | B9: 8 | C9: =C8 -> 1 | D9: =D8 -> 28.03.2024 | E9: =E8 -> SFG-FRBNET-MEM-BOR-72X33X08 | F9: =F8 -> Restonic Hotel Motel Bonnell Euro Top Memory Border 72X33X08 | G9: =G8 -> SFG-FRBNET-MEM-BOR-72X33X08 | H9: =H8 -> Restonic Hotel Motel Bonnell Euro Top Memory Border 72X33X08 | I9: Standard | J9: Production | K9: TAIL-BORDER | L9: NOS | M9: 1 | N9: MRP&Rollup | O9: CBESFG | P9: 80 | Q9: I | R9: RMI-BREATHER-GOLD | S9: BREATHER SET GOLD ROUND | T9: SET | U9: 2 | V9: CBEWIP | W9: Backflush | X9: Active | Y9: =RIGHT(E9,8) -> 72X33X08 | Z9: =LEFT(Y9,2) -> 72 | AA9: =MID(Y9,4,2) -> 33 | AB9: =RIGHT(Y9,2) -> 08 | AC9: =AC8 -> 72 | AD9: =AD8 -> 33 | AG9: =U9 -> 2 | AH9: =VLOOKUP(R9,'Rm-feb-24'!B:P,15,0) -> 4.6721 | AI9: =AG9*AH9 -> 9.3442 | AT9: =AT8 -> 144.148 | AU9: =AU8 -> 162
A10: 9
A11: 10 | B11: 1 | C11: 2 | D11: 28.03.2024 | E11: SFG-FRBNET-MEM-BOR-72X39X08 | F11: Restonic Hotel Motel Bonnell Euro Top Memory Border 72X39X08 | G11: =E11 -> SFG-FRBNET-MEM-BOR-72X39X08 | H11: =F11 -> Restonic Hotel Motel Bonnell Euro Top Memory Border 72X39X08 | I11: Standard | J11: Production | K11: TAIL-BORDER | L11: NOS | M11: 1 | N11: MRP&Rollup | O11: CBESFG | P11: 10 | Q11: I | R11: RM-THRD-QS-TKT40 | S11: THREAD TKT40 210D/3 PLY 10000MTS | T11: MTR | U11: 5.6 | V11: CBEWIP | W11: Backflush | X11: Active | Y11: =RIGHT(E11,8) -> 72X39X08 | Z11: =LEFT(Y11,2) -> 72 | AA11: =MID(Y11,4,2) -> 39 | AB11: =RIGHT(Y11,2) -> 08 | AC11: =Z11 -> 72 | AD11: =AA11 -> 39 | AG11: =U11/10000 -> 0.00056 | AH11: =VLOOKUP(R11,'Rm-feb-24'!B:P,15,0) -> 231.1423 | AI11: =AG11*AH11 -> 0.12943969 | AJ11: =SUM(AI11:AI18) -> 150.67615 | AK11: =ROUND(AJ11,3) -> 150.676 | AL11: =AK11 -> 150.676 | AM11: =+AL11+AR11 -> 169.322 | AN11: =+SUM(((AL11*3%*18%))) -> 0.8136504 | AO11: =+SUM(((AL11*14.33%*53%))) -> 11.443692 | AP11: =+SUM(((AL11*5.92%*53%))) -> 4.7276102 | AQ11: =+SUM(((AL11*2.08%*53%))) -> 1.6610522 | AR11: =SUM(AN11:AQ11) -> 18.646004 | AS11: =ROUNDUP(AM11,0) -> 170 | AT11: =AL11 -> 150.676 | AU11: =AS11 -> 170
A12: 11 | B12: 2 | C12: =C11 -> 2 | D12: =D11 -> 28.03.2024 | E12: =E11 -> SFG-FRBNET-MEM-BOR-72X39X08 | F12: =F11 -> Restonic Hotel Motel Bonnell Euro Top Memory Border 72X39X08 | G12: =G11 -> SFG-FRBNET-MEM-BOR-72X39X08 | H12: =H11 -> Restonic Hotel Motel Bonnell Euro Top Memory Border 72X39X08 | I12: Standard | J12: Production | K12: TAIL-BORDER | L12: NOS | M12: 1 | N12: MRP&Rollup | O12: CBESFG | P12: 20 | Q12: I | R12: HW-CTON-THREAD | S12: COTTON THREAD WHITE 3PLY | T12: MTR | U12: 5 | V12: CBEWIP | W12: Backflush | X12: Active | Y12: =RIGHT(E12,8) -> 72X39X08 | Z12: =LEFT(Y12,2) -> 72 | AA12: =MID(Y12,4,2) -> 39 | AB12: =RIGHT(Y12,2) -> 08 | AC12: =AC11 -> 72 | AD12: =AD11 -> 39 | AG12: =U12/5000 -> 0.001 | AH12: =VLOOKUP(R12,'Rm-feb-24'!B:P,15,0) -> 58 | AI12: =AG12*AH12 -> 0.058 | AT12: =AT11 -> 150.676 | AU12: =AU11 -> 170
A13: 12 | B13: 3 | C13: =C12 -> 2 | D13: =D12 -> 28.03.2024 | E13: =E12 -> SFG-FRBNET-MEM-BOR-72X39X08 | F13: =F12 -> Restonic Hotel Motel Bonnell Euro Top Memory Border 72X39X08 | G13: =G12 -> SFG-FRBNET-MEM-BOR-72X39X08 | H13: =H12 -> Restonic Hotel Motel Bonnell Euro Top Memory Border 72X39X08 | I13: Standard | J13: Production | K13: TAIL-BORDER | L13: NOS | M13: 1 | N13: MRP&Rollup | O13: CBESFG | P13: 30 | Q13: I | R13: SFG-RTHTMT-BNPK-MEM-BOR-21CM | S13: Hotel Motel Poc ET-8 8MM/16D Pre Foam Memory Border 21 CM Height | T13: MTR | U13: =AE13 -> 5.715 | V13: CBESFG | W13: Backflush | X13: Active | Y13: =RIGHT(E13,8) -> 72X39X08 | Z13: =LEFT(Y13,2) -> 72 | AA13: =MID(Y13,4,2) -> 39 | AB13: =RIGHT(Y13,2) -> 08 | AC13: =AC12 -> 72 | AD13: =AD12 -> 39 | AE13: =ROUNDUP(((((AC13+AD13)*2)+3)*0.0254),3) -> 5.715 | AG13: =U13 -> 5.715 | AH13: =VLOOKUP(R13,'SFG-RM'!A:B,2,0) -> 21.475377 | AI13: =AG13*AH13 -> 122.73178 | AT13: =AT12 -> 150.676 | AU13: =AU12 -> 170
A14: 13 | B14: 4 | C14: =C13 -> 2 | D14: =D13 -> 28.03.2024 | E14: =E13 -> SFG-FRBNET-MEM-BOR-72X39X08 | F14: =F13 -> Restonic Hotel Motel Bonnell Euro Top Memory Border 72X39X08 | G14: =G13 -> SFG-FRBNET-MEM-BOR-72X39X08 | H14: =H13 -> Restonic Hotel Motel Bonnell Euro Top Memory Border 72X39X08 | I14: Standard | J14: Production | K14: TAIL-BORDER | L14: NOS | M14: 1 | N14: MRP&Rollup | O14: CBESFG | P14: 40 | Q14: I | R14: RMI-HCC-SDE-LBL | S14: HOTEL COMFORT CARE SIDE LABEL (IMPORT) | T14: NOS | U14: 1 | V14: CBEWIP | W14: Backflush | X14: Active | Y14: =RIGHT(E14,8) -> 72X39X08 | Z14: =LEFT(Y14,2) -> 72 | AA14: =MID(Y14,4,2) -> 39 | AB14: =RIGHT(Y14,2) -> 08 | AC14: =AC13 -> 72 | AD14: =AD13 -> 39 | AE14: =ROUNDUP(((((72+30)*2)+3)*0.0254),3) -> 5.258 | AG14: =U14 -> 1 | AH14: =VLOOKUP(R14,'Rm-feb-24'!B:P,15,0) -> 5.9957 | AI14: =AG14*AH14 -> 5.9957 | AT14: =AT13 -> 150.676 | AU14: =AU13 -> 170
A15: 14 | B15: 5 | C15: =C14 -> 2 | D15: =D14 -> 28.03.2024 | E15: =E14 -> SFG-FRBNET-MEM-BOR-72X39X08 | F15: =F14 -> Restonic Hotel Motel Bonnell Euro Top Memory Border 72X39X08 | G15: =G14 -> SFG-FRBNET-MEM-BOR-72X39X08 | H15: =H14 -> Restonic Hotel Motel Bonnell Euro Top Memory Border 72X39X08 | I15: Standard | J15: Production | K15: TAIL-BORDER | L15: NOS | M15: 1 | N15: MRP&Rollup | O15: CBESFG | P15: 50 | Q15: I | R15: RML-MRP-BACK-LBL | S15: MRP BACK LABEL(PLAIN) | T15: NOS | U15: 1 | V15: CBEWIP | W15: Backflush | X15: Active | Y15: =RIGHT(E15,8) -> 72X39X08 | Z15: =LEFT(Y15,2) -> 72 | AA15: =MID(Y15,4,2) -> 39 | AB15: =RIGHT(Y15,2) -> 08 | AC15: =AC14 -> 72 | AD15: =AD14 -> 39 | AG15: =U15 -> 1 | AH15: =VLOOKUP(R15,'Rm-feb-24'!B:P,15,0) -> 1.3275 | AI15: =AG15*AH15 -> 1.3275 | AT15: =AT14 -> 150.676 | AU15: =AU14 -> 170
A16: 15 | B16: 6 | C16: =C15 -> 2 | D16: =D15 -> 28.03.2024 | E16: =E15 -> SFG-FRBNET-MEM-BOR-72X39X08 | F16: =F15 -> Restonic Hotel Motel Bonnell Euro Top Memory Border 72X39X08 | G16: =G15 -> SFG-FRBNET-MEM-BOR-72X39X08 | H16: =H15 -> Restonic Hotel Motel Bonnell Euro Top Memory Border 72X39X08 | I16: Standard | J16: Production | K16: TAIL-BORDER | L16: NOS | M16: 1 | N16: MRP&Rollup | O16: CBESFG | P16: 60 | Q16: I | R16: RML-DRN-LBL | S16: DIRECTION LABEL | T16: NOS | U16: 1 | V16: CBEWIP | W16: Backflush | X16: Active | Y16: =RIGHT(E16,8) -> 72X39X08 | Z16: =LEFT(Y16,2) -> 72 | AA16: =MID(Y16,4,2) -> 39 | AB16: =RIGHT(Y16,2) -> 08 | AC16: =AC15 -> 72 | AD16: =AD15 -> 39 | AG16: =U16 -> 1 | AH16: =VLOOKUP(R16,'Rm-feb-24'!B:P,15,0) -> 1.7318 | AI16: =AG16*AH16 -> 1.7318 | AT16: =AT15 -> 150.676 | AU16: =AU15 -> 170
A17: 16 | B17: 7 | C17: =C16 -> 2 | D17: =D16 -> 28.03.2024 | E17: =E16 -> SFG-FRBNET-MEM-BOR-72X39X08 | F17: =F16 -> Restonic Hotel Motel Bonnell Euro Top Memory Border 72X39X08 | G17: =G16 -> SFG-FRBNET-MEM-BOR-72X39X08 | H17: =H16 -> Restonic Hotel Motel Bonnell Euro Top Memory Border 72X39X08 | I17: Standard | J17: Production | K17: TAIL-BORDER | L17: NOS | M17: 1 | N17: MRP&Rollup | O17: CBESFG | P17: 70 | Q17: I | R17: SFG-RTHTMT-MEM-HANDLE | S17: Restonic Hotel Motel Memory Handle | T17: MTR | U17: 0.64 | V17: CBESFG | W17: Backflush | X17: Active | Y17: =RIGHT(E17,8) -> 72X39X08 | Z17: =LEFT(Y17,2) -> 72 | AA17: =MID(Y17,4,2) -> 39 | AB17: =RIGHT(Y17,2) -> 08 | AC17: =AC16 -> 72 | AD17: =AD16 -> 39 | AG17: =U17 -> 0.64 | AH17: =VLOOKUP(R17,'SFG-RM'!A:B,2,0) -> 14.621455 | AI17: =AG17*AH17 -> 9.3577314 | AT17: =AT16 -> 150.676 | AU17: =AU16 -> 170
A18: 17 | B18: 8 | C18: =C17 -> 2 | D18: =D17 -> 28.03.2024 | E18: =E17 -> SFG-FRBNET-MEM-BOR-72X39X08 | F18: =F17 -> Restonic Hotel Motel Bonnell Euro Top Memory Border 72X39X08 | G18: =G17 -> SFG-FRBNET-MEM-BOR-72X39X08 | H18: =H17 -> Restonic Hotel Motel Bonnell Euro Top Memory Border 72X39X08 | I18: Standard | J18: Production | K18: TAIL-BORDER | L18: NOS | M18: 1 | N18: MRP&Rollup | O18: CBESFG | P18: 80 | Q18: I | R18: RMI-BREATHER-GOLD | S18: BREATHER SET GOLD ROUND | T18: SET | U18: 2 | V18: CBEWIP | W18: Backflush | X18: Active | Y18: =RIGHT(E18,8) -> 72X39X08 | Z18: =LEFT(Y18,2) -> 72 | AA18: =MID(Y18,4,2) -> 39 | AB18: =RIGHT(Y18,2) -> 08 | AC18: =AC17 -> 72 | AD18: =AD17 -> 39 | AG18: =U18 -> 2 | AH18: =VLOOKUP(R18,'Rm-feb-24'!B:P,15,0) -> 4.6721 | AI18: =AG18*AH18 -> 9.3442 | AT18: =AT17 -> 150.676 | AU18: =AU17 -> 170
A19: 18
A20: 19 | B20: 1 | C20: 3 | D20: 28.03.2024 | E20: SFG-FRBNET-MEM-BOR-72X45X08 | F20: Restonic Hotel Motel Bonnell Euro Top Memory Border 72X45X08 | G20: =E20 -> SFG-FRBNET-MEM-BOR-72X45X08 | H20: =F20 -> Restonic Hotel Motel Bonnell Euro Top Memory Border 72X45X08 | I20: Standard | J20: Production | K20: TAIL-BORDER | L20: NOS | M20: 1 | N20: MRP&Rollup | O20: CBESFG | P20: 10 | Q20: I | R20: RM-THRD-QS-TKT40 | S20: THREAD TKT40 210D/3 PLY 10000MTS | T20: MTR | U20: 5.6 | V20: CBEWIP | W20: Backflush | X20: Active | Y20: =RIGHT(E20,8) -> 72X45X08 | Z20: =LEFT(Y20,2) -> 72 | AA20: =MID(Y20,4,2) -> 45 | AB20: =RIGHT(Y20,2) -> 08 | AC20: =Z20 -> 72 | AD20: =AA20 -> 45 | AG20: =U20/10000 -> 0.00056 | AH20: =VLOOKUP(R20,'Rm-feb-24'!B:P,15,0) -> 231.1423 | AI20: =AG20*AH20 -> 0.12943969 | AJ20: =SUM(AI20:AI27) -> 157.22614 | AK20: =ROUND(AJ20,3) -> 157.226 | AL20: =AK20 -> 157.226 | AM20: =+AL20+AR20 -> 176.68256 | AN20: =+SUM(((AL20*3%*18%))) -> 0.8490204 | AO20: =+SUM(((AL20*14.33%*53%))) -> 11.941157 | AP20: =+SUM(((AL20*5.92%*53%))) -> 4.933123 | AQ20: =+SUM(((AL20*2.08%*53%))) -> 1.7332594 | AR20: =SUM(AN20:AQ20) -> 19.45656 | AS20: =ROUNDUP(AM20,0) -> 177 | AT20: =AL20 -> 157.226 | AU20: =AS20 -> 177
A21: 20 | B21: 2 | C21: =C20 -> 3 | D21: =D20 -> 28.03.2024 | E21: =E20 -> SFG-FRBNET-MEM-BOR-72X45X08 | F21: =F20 -> Restonic Hotel Motel Bonnell Euro Top Memory Border 72X45X08 | G21: =G20 -> SFG-FRBNET-MEM-BOR-72X45X08 | H21: =H20 -> Restonic Hotel Motel Bonnell Euro Top Memory Border 72X45X08 | I21: Standard | J21: Production | K21: TAIL-BORDER | L21: NOS | M21: 1 | N21: MRP&Rollup | O21: CBESFG | P21: 20 | Q21: I | R21: HW-CTON-THREAD | S21: COTTON THREAD WHITE 3PLY | T21: MTR | U21: 5 | V21: CBEWIP | W21: Backflush | X21: Active | Y21: =RIGHT(E21,8) -> 72X45X08 | Z21: =LEFT(Y21,2) -> 72 | AA21: =MID(Y21,4,2) -> 45 | AB21: =RIGHT(Y21,2) -> 08 | AC21: =AC20 -> 72 | AD21: =AD20 -> 45 | AG21: =U21/5000 -> 0.001 | AH21: =VLOOKUP(R21,'Rm-feb-24'!B:P,15,0) -> 58 | AI21: =AG21*AH21 -> 0.058 | AT21: =AT20 -> 157.226 | AU21: =AU20 -> 177
A22: 21 | B22: 3 | C22: =C21 -> 3 | D22: =D21 -> 28.03.2024 | E22: =E21 -> SFG-FRBNET-MEM-BOR-72X45X08 | F22: =F21 -> Restonic Hotel Motel Bonnell Euro Top Memory Border 72X45X08 | G22: =G21 -> SFG-FRBNET-MEM-BOR-72X45X08 | H22: =H21 -> Restonic Hotel Motel Bonnell Euro Top Memory Border 72X45X08 | I22: Standard | J22: Production | K22: TAIL-BORDER | L22: NOS | M22: 1 | N22: MRP&Rollup | O22: CBESFG | P22: 30 | Q22: I | R22: SFG-RTHTMT-BNPK-MEM-BOR-21CM | S22: Hotel Motel Poc ET-8 8MM/16D Pre Foam Memory Border 21 CM Height | T22: MTR | U22: =AE22 -> 6.02 | V22: CBESFG | W22: Backflush | X22: Active | Y22: =RIGHT(E22,8) -> 72X45X08 | Z22: =LEFT(Y22,2) -> 72 | AA22: =MID(Y22,4,2) -> 45 | AB22: =RIGHT(Y22,2) -> 08 | AC22: =AC21 -> 72 | AD22: =AD21 -> 45 | AE22: =ROUNDUP(((((AC22+AD22)*2)+3)*0.0254),3) -> 6.02 | AG22: =U22 -> 6.02 | AH22: =VLOOKUP(R22,'SFG-RM'!A:B,2,0) -> 21.475377 | AI22: =AG22*AH22 -> 129.28177 | AT22: =AT21 -> 157.226 | AU22: =AU21 -> 177
A23: 22 | B23: 4 | C23: =C22 -> 3 | D23: =D22 -> 28.03.2024 | E23: =E22 -> SFG-FRBNET-MEM-BOR-72X45X08 | F23: =F22 -> Restonic Hotel Motel Bonnell Euro Top Memory Border 72X45X08 | G23: =G22 -> SFG-FRBNET-MEM-BOR-72X45X08 | H23: =H22 -> Restonic Hotel Motel Bonnell Euro Top Memory Border 72X45X08 | I23: Standard | J23: Production | K23: TAIL-BORDER | L23: NOS | M23: 1 | N23: MRP&Rollup | O23: CBESFG | P23: 40 | Q23: I | R23: RMI-HCC-SDE-LBL | S23: HOTEL COMFORT CARE SIDE LABEL (IMPORT) | T23: NOS | U23: 1 | V23: CBEWIP | W23: Backflush | X23: Active | Y23: =RIGHT(E23,8) -> 72X45X08 | Z23: =LEFT(Y23,2) -> 72 | AA23: =MID(Y23,4,2) -> 45 | AB23: =RIGHT(Y23,2) -> 08 | AC23: =AC22 -> 72 | AD23: =AD22 -> 45 | AE23: =ROUNDUP(((((72+30)*2)+3)*0.0254),3) -> 5.258 | AG23: =U23 -> 1 | AH23: =VLOOKUP(R23,'Rm-feb-24'!B:P,15,0) -> 5.9957 | AI23: =AG23*AH23 -> 5.9957 | AT23: =AT22 -> 157.226 | AU23: =AU22 -> 177
A24: 23 | B24: 5 | C24: =C23 -> 3 | D24: =D23 -> 28.03.2024 | E24: =E23 -> SFG-FRBNET-MEM-BOR-72X45X08 | F24: =F23 -> Restonic Hotel Motel Bonnell Euro Top Memory Border 72X45X08 | G24: =G23 -> SFG-FRBNET-MEM-BOR-72X45X08 | H24: =H23 -> Restonic Hotel Motel Bonnell Euro Top Memory Border 72X45X08 | I24: Standard | J24: Production | K24: TAIL-BORDER | L24: NOS | M24: 1 | N24: MRP&Rollup | O24: CBESFG | P24: 50 | Q24: I | R24: RML-MRP-BACK-LBL | S24: MRP BACK LABEL(PLAIN) | T24: NOS | U24: 1 | V24: CBEWIP | W24: Backflush | X24: Active | Y24: =RIGHT(E24,8) -> 72X45X08 | Z24: =LEFT(Y24,2) -> 72 | AA24: =MID(Y24,4,2) -> 45 | AB24: =RIGHT(Y24,2) -> 08 | AC24: =AC23 -> 72 | AD24: =AD23 -> 45 | AG24: =U24 -> 1 | AH24: =VLOOKUP(R24,'Rm-feb-24'!B:P,15,0) -> 1.3275 | AI24: =AG24*AH24 -> 1.3275 | AT24: =AT23 -> 157.226 | AU24: =AU23 -> 177
A25: 24 | B25: 6 | C25: =C24 -> 3 | D25: =D24 -> 28.03.2024 | E25: =E24 -> SFG-FRBNET-MEM-BOR-72X45X08 | F25: =F24 -> Restonic Hotel Motel Bonnell Euro Top Memory Border 72X45X08 | G25: =G24 -> SFG-FRBNET-MEM-BOR-72X45X08 | H25: =H24 -> Restonic Hotel Motel Bonnell Euro Top Memory Border 72X45X08 | I25: Standard | J25: Production | K25: TAIL-BORDER | L25: NOS | M25: 1 | N25: MRP&Rollup | O25: CBESFG | P25: 60 | Q25: I | R25: RML-DRN-LBL | S25: DIRECTION LABEL | T25: NOS | U25: 1 | V25: CBEWIP | W25: Backflush | X25: Active | Y25: =RIGHT(E25,8) -> 72X45X08 | Z25: =LEFT(Y25,2) -> 72 | AA25: =MID(Y25,4,2) -> 45 | AB25: =RIGHT(Y25,2) -> 08 | AC25: =AC24 -> 72 | AD25: =AD24 -> 45 | AG25: =U25 -> 1 | AH25: =VLOOKUP(R25,'Rm-feb-24'!B:P,15,0) -> 1.7318 | AI25: =AG25*AH25 -> 1.7318 | AT25: =AT24 -> 157.226 | AU25: =AU24 -> 177
A26: 25 | B26: 7 | C26: =C25 -> 3 | D26: =D25 -> 28.03.2024 | E26: =E25 -> SFG-FRBNET-MEM-BOR-72X45X08 | F26: =F25 -> Restonic Hotel Motel Bonnell Euro Top Memory Border 72X45X08 | G26: =G25 -> SFG-FRBNET-MEM-BOR-72X45X08 | H26: =H25 -> Restonic Hotel Motel Bonnell Euro Top Memory Border 72X45X08 | I26: Standard | J26: Production | K26: TAIL-BORDER | L26: NOS | M26: 1 | N26: MRP&Rollup | O26: CBESFG | P26: 70 | Q26: I | R26: SFG-RTHTMT-MEM-HANDLE | S26: Restonic Hotel Motel Memory Handle | T26: MTR | U26: 0.64 | V26: CBESFG | W26: Backflush | X26: Active | Y26: =RIGHT(E26,8) -> 72X45X08 | Z26: =LEFT(Y26,2) -> 72 | AA26: =MID(Y26,4,2) -> 45 | AB26: =RIGHT(Y26,2) -> 08 | AC26: =AC25 -> 72 | AD26: =AD25 -> 45 | AG26: =U26 -> 0.64 | AH26: =VLOOKUP(R26,'SFG-RM'!A:B,2,0) -> 14.621455 | AI26: =AG26*AH26 -> 9.3577314 | AT26: =AT25 -> 157.226 | AU26: =AU25 -> 177
A27: 26 | B27: 8 | C27: =C26 -> 3 | D27: =D26 -> 28.03.2024 | E27: =E26 -> SFG-FRBNET-MEM-BOR-72X45X08 | F27: =F26 -> Restonic Hotel Motel Bonnell Euro Top Memory Border 72X45X08 | G27: =G26 -> SFG-FRBNET-MEM-BOR-72X45X08 | H27: =H26 -> Restonic Hotel Motel Bonnell Euro Top Memory Border 72X45X08 | I27: Standard | J27: Production | K27: TAIL-BORDER | L27: NOS | M27: 1 | N27: MRP&Rollup | O27: CBESFG | P27: 80 | Q27: I | R27: RMI-BREATHER-GOLD | S27: BREATHER SET GOLD ROUND | T27: SET | U27: 2 | V27: CBEWIP | W27: Backflush | X27: Active | Y27: =RIGHT(E27,8) -> 72X45X08 | Z27: =LEFT(Y27,2) -> 72 | AA27: =MID(Y27,4,2) -> 45 | AB27: =RIGHT(Y27,2) -> 08 | AC27: =AC26 -> 72 | AD27: =AD26 -> 45 | AG27: =U27 -> 2 | AH27: =VLOOKUP(R27,'Rm-feb-24'!B:P,15,0) -> 4.6721 | AI27: =AG27*AH27 -> 9.3442 | AT27: =AT26 -> 157.226 | AU27: =AU26 -> 177
A28: 27
A29: 28 | B29: 1 | C29: 4 | D29: 28.03.2024 | E29: SFG-FRBNET-MEM-BOR-72X51X08 | F29: Restonic Hotel Motel Bonnell Euro Top Memory Border 72X51X08 | G29: =E29 -> SFG-FRBNET-MEM-BOR-72X51X08 | H29: =F29 -> Restonic Hotel Motel Bonnell Euro Top Memory Border 72X51X08 | I29: Standard | J29: Production | K29: TAIL-BORDER | L29: NOS | M29: 1 | N29: MRP&Rollup | O29: CBESFG | P29: 10 | Q29: I | R29: RM-THRD-QS-TKT40 | S29: THREAD TKT40 210D/3 PLY 10000MTS | T29: MTR | U29: 5.6 | V29: CBEWIP | W29: Backflush | X29: Active | Y29: =RIGHT(E29,8) -> 72X51X08 | Z29: =LEFT(Y29,2) -> 72 | AA29: =MID(Y29,4,2) -> 51 | AB29: =RIGHT(Y29,2) -> 08 | AC29: =Z29 -> 72 | AD29: =AA29 -> 51 | AG29: =U29/10000 -> 0.00056 | AH29: =VLOOKUP(R29,'Rm-feb-24'!B:P,15,0) -> 231.1423 | AI29: =AG29*AH29 -> 0.12943969 | AJ29: =SUM(AI29:AI36) -> 163.77613 | AK29: =ROUND(AJ29,3) -> 163.776 | AL29: =AK29 -> 163.776 | AM29: =+AL29+AR29 -> 184.04312 | AN29: =+SUM(((AL29*3%*18%))) -> 0.8843904 | AO29: =+SUM(((AL29*14.33%*53%))) -> 12.438623 | AP29: =+SUM(((AL29*5.92%*53%))) -> 5.1386358 | AQ29: =+SUM(((AL29*2.08%*53%))) -> 1.8054666 | AR29: =SUM(AN29:AQ29) -> 20.267116 | AS29: =ROUNDUP(AM29,0) -> 185 | AT29: =AL29 -> 163.776 | AU29: =AS29 -> 185
A30: 29 | B30: 2 | C30: =C29 -> 4 | D30: =D29 -> 28.03.2024 | E30: =E29 -> SFG-FRBNET-MEM-BOR-72X51X08 | F30: =F29 -> Restonic Hotel Motel Bonnell Euro Top Memory Border 72X51X08 | G30: =G29 -> SFG-FRBNET-MEM-BOR-72X51X08 | H30: =H29 -> Restonic Hotel Motel Bonnell Euro Top Memory Border 72X51X08 | I30: Standard | J30: Production | K30: TAIL-BORDER | L30: NOS | M30: 1 | N30: MRP&Rollup | O30: CBESFG | P30: 20 | Q30: I | R30: HW-CTON-THREAD | S30: COTTON THREAD WHITE 3PLY | T30: MTR | U30: 5 | V30: CBEWIP | W30: Backflush | X30: Active | Y30: =RIGHT(E30,8) -> 72X51X08 | Z30: =LEFT(Y30,2) -> 72 | AA30: =MID(Y30,4,2) -> 51 | AB30: =RIGHT(Y30,2) -> 08 | AC30: =AC29 -> 72 | AD30: =AD29 -> 51 | AG30: =U30/5000 -> 0.001 | AH30: =VLOOKUP(R30,'Rm-feb-24'!B:P,15,0) -> 58 | AI30: =AG30*AH30 -> 0.058 | AT30: =AT29 -> 163.776 | AU30: =AU29 -> 185
A31: 30 | B31: 3 | C31: =C30 -> 4 | D31: =D30 -> 28.03.2024 | E31: =E30 -> SFG-FRBNET-MEM-BOR-72X51X08 | F31: =F30 -> Restonic Hotel Motel Bonnell Euro Top Memory Border 72X51X08 | G31: =G30 -> SFG-FRBNET-MEM-BOR-72X51X08 | H31: =H30 -> Restonic Hotel Motel Bonnell Euro Top Memory Border 72X51X08 | I31: Standard | J31: Production | K31: TAIL-BORDER | L31: NOS | M31: 1 | N31: MRP&Rollup | O31: CBESFG | P31: 30 | Q31: I | R31: SFG-RTHTMT-BNPK-MEM-BOR-21CM | S31: Hotel Motel Poc ET-8 8MM/16D Pre Foam Memory Border 21 CM Height | T31: MTR | U31: =AE31 -> 6.325 | V31: CBESFG | W31: Backflush | X31: Active | Y31: =RIGHT(E31,8) -> 72X51X08 | Z31: =LEFT(Y31,2) -> 72 | AA31: =MID(Y31,4,2) -> 51 | AB31: =RIGHT(Y31,2) -> 08 | AC31: =AC30 -> 72 | AD31: =AD30 -> 51 | AE31: =ROUNDUP(((((AC31+AD31)*2)+3)*0.0254),3) -> 6.325 | AG31: =U31 -> 6.325 | AH31: =VLOOKUP(R31,'SFG-RM'!A:B,2,0) -> 21.475377 | AI31: =AG31*AH31 -> 135.83176 | AT31: =AT30 -> 163.776 | AU31: =AU30 -> 185
A32: 31 | B32: 4 | C32: =C31 -> 4 | D32: =D31 -> 28.03.2024 | E32: =E31 -> SFG-FRBNET-MEM-BOR-72X51X08 | F32: =F31 -> Restonic Hotel Motel Bonnell Euro Top Memory Border 72X51X08 | G32: =G31 -> SFG-FRBNET-MEM-BOR-72X51X08 | H32: =H31 -> Restonic Hotel Motel Bonnell Euro Top Memory Border 72X51X08 | I32: Standard | J32: Production | K32: TAIL-BORDER | L32: NOS | M32: 1 | N32: MRP&Rollup | O32: CBESFG | P32: 40 | Q32: I | R32: RMI-HCC-SDE-LBL | S32: HOTEL COMFORT CARE SIDE LABEL (IMPORT) | T32: NOS | U32: 1 | V32: CBEWIP | W32: Backflush | X32: Active | Y32: =RIGHT(E32,8) -> 72X51X08 | Z32: =LEFT(Y32,2) -> 72 | AA32: =MID(Y32,4,2) -> 51 | AB32: =RIGHT(Y32,2) -> 08 | AC32: =AC31 -> 72 | AD32: =AD31 -> 51 | AE32: =ROUNDUP(((((72+30)*2)+3)*0.0254),3) -> 5.258 | AG32: =U32 -> 1 | AH32: =VLOOKUP(R32,'Rm-feb-24'!B:P,15,0) -> 5.9957 | AI32: =AG32*AH32 -> 5.9957 | AT32: =AT31 -> 163.776 | AU32: =AU31 -> 185
A33: 32 | B33: 5 | C33: =C32 -> 4 | D33: =D32 -> 28.03.2024 | E33: =E32 -> SFG-FRBNET-MEM-BOR-72X51X08 | F33: =F32 -> Restonic Hotel Motel Bonnell Euro Top Memory Border 72X51X08 | G33: =G32 -> SFG-FRBNET-MEM-BOR-72X51X08 | H33: =H32 -> Restonic Hotel Motel Bonnell Euro Top Memory Border 72X51X08 | I33: Standard | J33: Production | K33: TAIL-BORDER | L33: NOS | M33: 1 | N33: MRP&Rollup | O33: CBESFG | P33: 50 | Q33: I | R33: RML-MRP-BACK-LBL | S33: MRP BACK LABEL(PLAIN) | T33: NOS | U33: 1 | V33: CBEWIP | W33: Backflush | X33: Active | Y33: =RIGHT(E33,8) -> 72X51X08 | Z33: =LEFT(Y33,2) -> 72 | AA33: =MID(Y33,4,2) -> 51 | AB33: =RIGHT(Y33,2) -> 08 | AC33: =AC32 -> 72 | AD33: =AD32 -> 51 | AG33: =U33 -> 1 | AH33: =VLOOKUP(R33,'Rm-feb-24'!B:P,15,0) -> 1.3275 | AI33: =AG33*AH33 -> 1.3275 | AT33: =AT32 -> 163.776 | AU33: =AU32 -> 185
A34: 33 | B34: 6 | C34: =C33 -> 4 | D34: =D33 -> 28.03.2024 | E34: =E33 -> SFG-FRBNET-MEM-BOR-72X51X08 | F34: =F33 -> Restonic Hotel Motel Bonnell Euro Top Memory Border 72X51X08 | G34: =G33 -> SFG-FRBNET-MEM-BOR-72X51X08 | H34: =H33 -> Restonic Hotel Motel Bonnell Euro Top Memory Border 72X51X08 | I34: Standard | J34: Production | K34: TAIL-BORDER | L34: NOS | M34: 1 | N34: MRP&Rollup | O34: CBESFG | P34: 60 | Q34: I | R34: RML-DRN-LBL | S34: DIRECTION LABEL | T34: NOS | U34: 1 | V34: CBEWIP | W34: Backflush | X34: Active | Y34: =RIGHT(E34,8) -> 72X51X08 | Z34: =LEFT(Y34,2) -> 72 | AA34: =MID(Y34,4,2) -> 51 | AB34: =RIGHT(Y34,2) -> 08 | AC34: =AC33 -> 72 | AD34: =AD33 -> 51 | AG34: =U34 -> 1 | AH34: =VLOOKUP(R34,'Rm-feb-24'!B:P,15,0) -> 1.7318 | AI34: =AG34*AH34 -> 1.7318 | AT34: =AT33 -> 163.776 | AU34: =AU33 -> 185
A35: 34 | B35: 7 | C35: =C34 -> 4 | D35: =D34 -> 28.03.2024 | E35: =E34 -> SFG-FRBNET-MEM-BOR-72X51X08 | F35: =F34 -> Restonic Hotel Motel Bonnell Euro Top Memory Border 72X51X08 | G35: =G34 -> SFG-FRBNET-MEM-BOR-72X51X08 | H35: =H34 -> Restonic Hotel Motel Bonnell Euro Top Memory Border 72X51X08 | I35: Standard | J35: Production | K35: TAIL-BORDER | L35: NOS | M35: 1 | N35: MRP&Rollup | O35: CBESFG | P35: 70 | Q35: I | R35: SFG-RTHTMT-MEM-HANDLE | S35: Restonic Hotel Motel Memory Handle | T35: MTR | U35: 0.64 | V35: CBESFG | W35: Backflush | X35: Active | Y35: =RIGHT(E35,8) -> 72X51X08 | Z35: =LEFT(Y35,2) -> 72 | AA35: =MID(Y35,4,2) -> 51 | AB35: =RIGHT(Y35,2) -> 08 | AC35: =AC34 -> 72 | AD35: =AD34 -> 51 | AG35: =U35 -> 0.64 | AH35: =VLOOKUP(R35,'SFG-RM'!A:B,2,0) -> 14.621455 | AI35: =AG35*AH35 -> 9.3577314 | AT35: =AT34 -> 163.776 | AU35: =AU34 -> 185
A36: 35 | B36: 8 | C36: =C35 -> 4 | D36: =D35 -> 28.03.2024 | E36: =E35 -> SFG-FRBNET-MEM-BOR-72X51X08 | F36: =F35 -> Restonic Hotel Motel Bonnell Euro Top Memory Border 72X51X08 | G36: =G35 -> SFG-FRBNET-MEM-BOR-72X51X08 | H36: =H35 -> Restonic Hotel Motel Bonnell Euro Top Memory Border 72X51X08 | I36: Standard | J36: Production | K36: TAIL-BORDER | L36: NOS | M36: 1 | N36: MRP&Rollup | O36: CBESFG | P36: 80 | Q36: I | R36: RMI-BREATHER-GOLD | S36: BREATHER SET GOLD ROUND | T36: SET | U36: 2 | V36: CBEWIP | W36: Backflush | X36: Active | Y36: =RIGHT(E36,8) -> 72X51X08 | Z36: =LEFT(Y36,2) -> 72 | AA36: =MID(Y36,4,2) -> 51 | AB36: =RIGHT(Y36,2) -> 08 | AC36: =AC35 -> 72 | AD36: =AD35 -> 51 | AG36: =U36 -> 2 | AH36: =VLOOKUP(R36,'Rm-feb-24'!B:P,15,0) -> 4.6721 | AI36: =AG36*AH36 -> 9.3442 | AT36: =AT35 -> 163.776 | AU36: =AU35 -> 185
A37: 36
A38: 37 | B38: 1 | C38: 5 | D38: 28.03.2024 | E38: SFG-FRBNET-MEM-BOR-72X54X08 | F38: Restonic Hotel Motel Bonnell Euro Top Memory Border 72X54X08 | G38: =E38 -> SFG-FRBNET-MEM-BOR-72X54X08 | H38: =F38 -> Restonic Hotel Motel Bonnell Euro Top Memory Border 72X54X08 | I38: Standard | J38: Production | K38: TAIL-BORDER | L38: NOS | M38: 1 | N38: MRP&Rollup | O38: CBESFG | P38: 10 | Q38: I | R38: RM-THRD-QS-TKT40 | S38: THREAD TKT40 210D/3 PLY 10000MTS | T38: MTR | U38: 5.6 | V38: CBEWIP | W38: Backflush | X38: Active | Y38: =RIGHT(E38,8) -> 72X54X08 | Z38: =LEFT(Y38,2) -> 72 | AA38: =MID(Y38,4,2) -> 54 | AB38: =RIGHT(Y38,2) -> 08 | AC38: =Z38 -> 72 | AD38: =AA38 -> 54 | AG38: =U38/10000 -> 0.00056 | AH38: =VLOOKUP(R38,'Rm-feb-24'!B:P,15,0) -> 231.1423 | AI38: =AG38*AH38 -> 0.12943969 | AJ38: =SUM(AI38:AI45) -> 167.04039 | AK38: =ROUND(AJ38,3) -> 167.04 | AL38: =AK38 -> 167.04 | AM38: =+AL38+AR38 -> 187.71103 | AN38: =+SUM(((AL38*3%*18%))) -> 0.902016 | AO38: =+SUM(((AL38*14.33%*53%))) -> 12.686521 | AP38: =+SUM(((AL38*5.92%*53%))) -> 5.241047 | AQ38: =+SUM(((AL38*2.08%*53%))) -> 1.841449 | AR38: =SUM(AN38:AQ38) -> 20.671033 | AS38: =ROUNDUP(AM38,0) -> 188 | AT38: =AL38 -> 167.04 | AU38: =AS38 -> 188
A39: 38 | B39: 2 | C39: =C38 -> 5 | D39: =D38 -> 28.03.2024 | E39: =E38 -> SFG-FRBNET-MEM-BOR-72X54X08 | F39: =F38 -> Restonic Hotel Motel Bonnell Euro Top Memory Border 72X54X08 | G39: =G38 -> SFG-FRBNET-MEM-BOR-72X54X08 | H39: =H38 -> Restonic Hotel Motel Bonnell Euro Top Memory Border 72X54X08 | I39: Standard | J39: Production | K39: TAIL-BORDER | L39: NOS | M39: 1 | N39: MRP&Rollup | O39: CBESFG | P39: 20 | Q39: I | R39: HW-CTON-THREAD | S39: COTTON THREAD WHITE 3PLY | T39: MTR | U39: 5 | V39: CBEWIP | W39: Backflush | X39: Active | Y39: =RIGHT(E39,8) -> 72X54X08 | Z39: =LEFT(Y39,2) -> 72 | AA39: =MID(Y39,4,2) -> 54 | AB39: =RIGHT(Y39,2) -> 08 | AC39: =AC38 -> 72 | AD39: =AD38 -> 54 | AG39: =U39/5000 -> 0.001 | AH39: =VLOOKUP(R39,'Rm-feb-24'!B:P,15,0) -> 58 | AI39: =AG39*AH39 -> 0.058 | AT39: =AT38 -> 167.04 | AU39: =AU38 -> 188
A40: 39 | B40: 3 | C40: =C39 -> 5 | D40: =D39 -> 28.03.2024 | E40: =E39 -> SFG-FRBNET-MEM-BOR-72X54X08 | F40: =F39 -> Restonic Hotel Motel Bonnell Euro Top Memory Border 72X54X08 | G40: =G39 -> SFG-FRBNET-MEM-BOR-72X54X08 | H40: =H39 -> Restonic Hotel Motel Bonnell Euro Top Memory Border 72X54X08 | I40: Standard | J40: Production | K40: TAIL-BORDER | L40: NOS | M40: 1 | N40: MRP&Rollup | O40: CBESFG | P40: 30 | Q40: I | R40: SFG-RTHTMT-BNPK-MEM-BOR-21CM | S40: Hotel Motel Poc ET-8 8MM/16D Pre Foam Memory Border 21 CM Height | T40: MTR | U40: =AE40 -> 6.477 | V40: CBESFG | W40: Backflush | X40: Active | Y40: =RIGHT(E40,8) -> 72X54X08 | Z40: =LEFT(Y40,2) -> 72 | AA40: =MID(Y40,4,2) -> 54 | AB40: =RIGHT(Y40,2) -> 08 | AC40: =AC39 -> 72 | AD40: =AD39 -> 54 | AE40: =ROUNDUP(((((AC40+AD40)*2)+3)*0.0254),3) -> 6.477 | AG40: =U40 -> 6.477 | AH40: =VLOOKUP(R40,'SFG-RM'!A:B,2,0) -> 21.475377 | AI40: =AG40*AH40 -> 139.09602 | AT40: =AT39 -> 167.04 | AU40: =AU39 -> 188
...

Sheet SFG-RM
A1: Row Labels | B1: Sum of Feb-24-Total
A2: BNAS-106X72X130 | B2: 1650.0082
A3: BNAS-13X13X100 | B3: 27.727734
A4: BNAS-13X13X130 | B4: 32.182134
A5: BNAS-13X13X150 | B5: 36.559734
A6: BNAS-13X13X90 | B6: 27.113334
A7: BNAS-18X18X100 | B7: 47.467619
A8: BNAS-18X18X130 | B8: 54.891619
A9: BNAS-20X18X100 | B9: 55.968766
A10: BNAS-20X18X130 | B10: 64.877566
A11: BNAS-20X18X150 | B11: 73.632766
A12: BNAS-20X18X90 | B12: 54.739966
A13: BNAS-24X60X130 | B13: 273.74261
... A29219: Grand Total | B29219: 18179053

Sheet Rm-feb-24
A1: SI.No | B1: Item Code | C1: Item Desc | D1: UOM | E1: Warehouse | F1: Opening Stock Qty | G1: Opening Stock Rate | H1: Opening Stock Value | I1: Stock In Qty | J1: Stock In Rate | K1: Stock In Value | L1: Stock Out Qty | M1: Stock Out Rate | N1: Stock Out Value | O1: Closing Stock Qty | P1: Closing Stock Rate | Q1: Closing Stock Value | R1: Item Account Group | S1: Item Account Group Desc | T1: Item Category
A2: 33 | B2: RML-CS-RTC-PLUSH-7.5 | C2: CORNER SHOES RESTONIC PLUSH - 7.5" | D2: NOS | E2: CBERM | F2: 900 | G2: 10.2033 | H2: 9182.97 | I2: 600 | J2: 10 | K2: 6000 | L2: 300 | M2: 10.1452 | N2: 3043.57 | O2: 1200 | P2: 10.1162 | Q2: 12139.4 | R2: LCE | S2: Label,CnrShoe,CentreBand,EdgeTape-10195 | T2: MATRESS
A3: 35 | B3: RML-CS-RTC-PLUSH-9.5 | C3: CORNER SHOES RESTONIC PLUSH - 9.5" | D3: NOS | E3: CBERM | F3: 1000 | G3: 10.3332 | H3: 10333.16 | I3: 500 | J3: 12.3 | K3: 6150 | L3: 200 | M3: 10.9888 | N3: 2197.76 | O3: 1300 | P3: 10.9888 | Q3: 14285.4 | R3: LCE | S3: Label,CnrShoe,CentreBand,EdgeTape-10195 | T3: MATRESS
A4: 37 | B4: RML-CS-SPG-6.5" | C4: CORNER SHOES. SPINE GUARD - 6.5" | D4: NOS | E4: CBERM | F4: 1200 | G4: 10.7018 | H4: 12842.19 | I4: 0 | K4: 0 | L4: 200 | M4: 10.7018 | N4: 2140.36 | O4: 1000 | P4: 10.7018 | Q4: 10701.83 | R4: LCE | S4: Label,CnrShoe,CentreBand,EdgeTape-10195 | T4: MATRESS
A5: 42 | B5: RML-CS-SPG-7.5" | C5: CORNER SHOES. SPINE GUARD - 7.5" | D5: NOS | E5: CBERM | F5: 1300 | G5: 10 | H5: 13000 | I5: 4800 | J5: 10 | K5: 48000 | L5: 3300 | M5: 10 | N5: 33000 | O5: 2800 | P5: 10 | Q5: 28000 | R5: LCE | S5: Label,CnrShoe,CentreBand,EdgeTape-10195 | T5: MATRESS
A6: 48 | B6: RML-CS-SPG-9.5" | C6: CORNER SHOES. SPINE GUARD - 9.5" | D6: NOS | E6: CBERM | F6: 1100 | G6: 10.48 | H6: 11528 | I6: 1000 | J6: 10.48 | K6: 10480 | L6: 1600 | M6: 10.48 | N6: 16768 | O6: 500 | P6: 10.48 | Q6: 5240 | R6: LCE | S6: Label,CnrShoe,CentreBand,EdgeTape-10195 | T6: MATRESS
A7: 56 | B7: RML-CS-SPK-10.5" | C7: CORNER SHOES. SPK - 10.5" | D7: NOS | E7: CBERM | F7: 1389 | G7: 9.7779 | H7: 13581.54 | I7: 0 | K7: 0 | L7: 0 | N7: 0 | O7: 1389 | P7: 9.7779 | Q7: 13581.54 | R7: LCE | S7: Label,CnrShoe,CentreBand,EdgeTape-10195 | T7: MATRESS
A8: 59 | B8: RML-CS-SPK-8.5" | C8: CORNER SHOES. SPK - 8.5" | D8: NOS | E8: CBERM | F8: 1000 | G8: 10.3146 | H8: 10314.55 | I8: 0 | K8: 0 | L8: 0 | N8: 0 | O8: 1000 | P8: 10.3146 | Q8: 10314.55 | R8: LCE | S8: Label,CnrShoe,CentreBand,EdgeTape-10195 | T8: MATRESS
A9: 63 | B9: RML-CS-SPK-BG-10.5 | C9: CORNER SHOES SPRINGKOIL BEIGE -10.5" | D9: NOS | E9: CBERM | F9: 400 | G9: 12.5 | H9: 5000 | I9: 0 | K9: 0 | L9: 0 | N9: 0 | O9: 400 | P9: 12.5 | Q9: 5000 | R9: LCE | S9: Label,CnrShoe,CentreBand,EdgeTape-10195 | T9: MATRESS
A10: 66 | B10: RML-CS-SPK-BG-7 | C10: CORNER SHOES SPRINGKOIL BEIGE -7" | D10: NOS | E10: CBERM | F10: 6500 | G10: 10 | H10: 65000 | I10: 0 | K10: 0 | L10: 400 | M10: 10 | N10: 4000 | O10: 6100 | P10: 10 | Q10: 61000 | R10: LCE | S10: Label,CnrShoe,CentreBand,EdgeTape-10195 | T10: MATRESS
A11: 67 | B11: RML-CS-SPK-BG-8.5 | C11: CORNER SHOES SPRINGKOIL BEIGE -8.5" | D11: NOS | E11: CBERM | F11: 3300 | G11: 10 | H11: 33000 | I11: 0 | K11: 0 | L11: 0 | N11: 0 | O11: 3300 | P11: 10 | Q11: 33000 | R11: LCE | S11: Label,CnrShoe,CentreBand,EdgeTape-10195 | T11: MATRESS
A12: 69 | B12: RML-CS-SPK-BL-10.5 | C12: CORNER SHOES SPRINGKOIL BLUE -10.5" | D12: NOS | E12: CBERM | F12: 500 | G12: 11.5625 | H12: 5781.25 | I12: 0 | K12: 0 | L12: 0 | N12: 0 | O12: 500 | P12: 11.5625 | Q12: 5781.25 | R12: LCE | S12: Label,CnrShoe,CentreBand,EdgeTape-10195 | T12: MATRESS
A13: 71 | B13: RML-CS-SPK-BL-6 | C13: CORNER SHOES SPRINGKOIL BLUE -6" | D13: NOS | E13: CBERM | F13: 2900 | G13: 10 | H13: 29000 | I13: 0 | K13: 0 | L13: 200 | M13: 10 | N13: 2000 | O13: 2700 | P13: 10 | Q13: 27000 | R13: LCE | S13: Label,CnrShoe,CentreBand,EdgeTape-10195 | T13: MATRESS
A14: 73 | B14: RML-CS-SPK-BL-7 | C14: CORNER SHOES SPRINGKOIL BLUE -7" | D14: NOS | E14: CBERM | F14: 21800 | G14: 8.6732 | H14: 189076.19 | I14: 50 | J14: 8.6732 | K14: 433.66 | L14: 6600 | M14: 8.6732 | N14: 57243.12 | O14: 15250 | P14: 8.6732 | Q14: 132266.73 | R14: LCE | S14: Label,CnrShoe,CentreBand,EdgeTape-10195 | T14: MATRESS
A15: 75 | B15: RML-CS-SPK-BL-7.5 | C15: CORNER SHOES SPRINGKOIL BLUE -7.5" | D15: NOS | E15: CBERM | F15: 1065 | G15: 10 | H15: 10650 | I15: 0 | K15: 0 | L15: 0 | N15: 0 | O15: 1065 | P15: 10 | Q15: 10650 | R15: LCE | S15: Label,CnrShoe,CentreBand,EdgeTape-10195 | T15: MATRESS
A16: 77 | B16: RML-CS-SPK-BL-8.5 | C16: CORNER SHOES SPRINGKOIL BLUE -8.5" | D16: NOS | E16: CBERM | F16: 4000 | G16: 10.2861 | H16: 41144.42 | I16: 100 | J16: 10.2861 | K16: 1028.61 | L16: 300 | M16: 10.2861 | N16: 3085.83 | O16: 3800 | P16: 10.2861 | Q16: 39087.2 | R16: LCE | S16: Label,CnrShoe,CentreBand,EdgeTape-10195 | T16: MATRESS
A17: 78 | B17: RML-CS-SPK-BW-10.5 | C17: CORNER SHOES SPRINGKOIL BROWN -10.5" | D17: NOS | E17: CBERM | F17: 800 | G17: 11.5625 | H17: 9250 | I17: 0 | K17: 0 | L17: 0 | N17: 0 | O17: 800 | P17: 11.5625 | Q17: 9250 | R17: LCE | S17: Label,CnrShoe,CentreBand,EdgeTape-10195 | T17: MATRESS
A18: 81 | B18: RML-CS-SPK-BW-6 | C18: CORNER SHOES SPRINGKOIL BROWN -6" | D18: NOS | E18: CBERM | F18: 500 | G18: 10 | H18: 5000 | I18: 0 | K18: 0 | L18: 100 | M18: 10 | N18: 1000 | O18: 400 | P18: 10 | Q18: 4000 | R18: LCE | S18: Label,CnrShoe,CentreBand,EdgeTape-10195 | T18: MATRESS
A19: 82 | B19: RML-CS-SPK-BW-7 | C19: CORNER SHOES SPRINGKOIL BROWN -7" | D19: NOS | E19: CBERM | F19: 4400 | G19: 10 | H19: 44000 | I19: 1000 | J19: 10 | K19: 10000 | L19: 2700 | M19: 10 | N19: 27000 | O19: 2700 | P19: 10 | Q19: 27000 | R19: LCE | S19: Label,CnrShoe,CentreBand,EdgeTape-10195 | T19: MATRESS
A20: 84 | B20: RML-CS-SPK-BW-7.5 | C20: CORNER SHOES SPRINGKOIL BROWN -7.5" | D20: NOS | E20: CBERM | F20: 555 | G20: 10 | H20: 5550 | I20: 0 | K20: 0 | L20: 0 | N20: 0 | O20: 555 | P20: 10 | Q20: 5550 | R20: LCE | S20: Label,CnrShoe,CentreBand,EdgeTape-10195 | T20: MATRESS
A21: 85 | B21: RML-CS-SPK-BW-8.5 | C21: CORNER SHOES SPRINGKOIL BROWN -8.5" | D21: NOS | E21: CBERM | F21: 3348 | G21: 10 | H21: 33480 | I21: 0 | K21: 0 | L21: 0 | N21: 0 | O21: 3348 | P21: 10 | Q21: 33480 | R21: LCE | S21: Label,CnrShoe,CentreBand,EdgeTape-10195 | T21: MATRESS
A22: 87 | B22: RML-CS-SPK-CR-10.5 | C22: CORNER SHOES SPRINGKOIL CREAM -10.5" | D22: NOS | E22: CBERM | F22: 800 | G22: 11.3889 | H22: 9111.11 | I22: 0 | K22: 0 | L22: 0 | N22: 0 | O22: 800 | P22: 11.3889 | Q22: 9111.11 | R22: LCE | S22: Label,CnrShoe,CentreBand,EdgeTape-10195 | T22: MATRESS
A23: 89 | B23: RML-CS-SPK-CR-6 | C23: CORNER SHOES SPRINGKOIL CREAM -6" | D23: NOS | E23: CBERM | F23: 400 | G23: 10 | H23: 4000 | I23: 0 | K23: 0 | L23: 100 | M23: 10 | N23: 1000 | O23: 300 | P23: 10 | Q23: 3000 | R23: LCE | S23: Label,CnrShoe,CentreBand,EdgeTape-10195 | T23: MATRESS
A24: 92 | B24: RML-CS-SPK-CR-7 | C24: CORNER SHOES SPRINGKOIL CREAM -7" | D24: NOS | E24: CBERM | F24: 4600 | G24: 10 | H24: 46000 | I24: 0 | K24: 0 | L24: 500 | M24: 10 | N24: 5000 | O24: 4100 | P24: 10 | Q24: 41000 | R24: LCE | S24: Label,CnrShoe,CentreBand,EdgeTape-10195 | T24: MATRESS
A25: 93 | B25: RML-CS-SPK-CR-7.5 | C25: CORNER SHOES SPRINGKOIL CREAM -7.5" | D25: NOS | E25: CBERM | F25: 280 | G25: 10 | H25: 2800 | I25: 0 | K25: 0 | L25: 0 | N25: 0 | O25: 280 | P25: 10 | Q25: 2800 | R25: LCE | S25: Label,CnrShoe,CentreBand,EdgeTape-10195 | T25: MATRESS
A26: 94 | B26: RML-CS-SPK-CR-8.5 | C26: CORNER SHOES SPRINGKOIL CREAM -8.5" | D26: NOS | E26: CBERM | F26: 2900 | G26: 10 | H26: 29000 | I26: 0 | K26: 0 | L26: 0 | N26: 0 | O26: 2900 | P26: 10 | Q26: 29000 | R26: LCE | S26: Label,CnrShoe,CentreBand,EdgeTape-10195 | T26: MATRESS
A27: 97 | B27: RML-CS-SPK-CT-6 | C27: PEPS SPRINGKOIL CROWN TOP CORNER SHOES 6" | D27: NOS | E27: CBERM | F27: 2000 | G27: 8.65 | H27: 17300 | I27: 14000 | J27: 8.65 | K27: 121100 | L27: 2400 | M27: 8.65 | N27: 20760 | O27: 13600 | P27: 8.65 | Q27: 117640 | R27: LCE | S27: Label,CnrShoe,CentreBand,EdgeTape-10195 | T27: MATRESS
A28: 102 | B28: RML-CS-SPK-CT-7.5 | C28: PEPS SPRINGKOIL CROWN TOP CORNER SHOES 7.5" | D28: NOS | E28: CBERM | F28: 1400 | G28: 9.9 | H28: 13860 | I28: 0 | K28: 0 | L28: 200 | M28: 9.9 | N28: 1980 | O28: 1200 | P28: 9.9 | Q28: 11880 | R28: LCE | S28: Label,CnrShoe,CentreBand,EdgeTape-10195 | T28: MATRESS
A29: 108 | B29: RML-CS-SPK-CT-9.25 | C29: PEPS SPRINGKOIL CROWN TOP CORNER SHOES 9.25" | D29: NOS | E29: CBERM | F29: 850 | G29: 15.3 | H29: 13005 | I29: 0 | K29: 0 | L29: 100 | M29: 15.3 | N29: 1530 | O29: 750 | P29: 15.3 | Q29: 11475 | R29: LCE | S29: Label,CnrShoe,CentreBand,EdgeTape-10195 | T29: MATRESS
A30: 110 | B30: RML-CS-SPK-GR-10.5 | C30: CORNER SHOES SPRINGKOIL GREY -10.5" | D30: NOS | E30: CBERM | F30: 400 | G30: 12.5 | H30: 5000 | I30: 0 | K30: 0 | L30: 0 | N30: 0 | O30: 400 | P30: 12.5 | Q30: 5000 | R30: LCE | S30: Label,CnrShoe,CentreBand,EdgeTape-10195 | T30: MATRESS
A31: 113 | B31: RML-CS-SPK-GR-7 | C31: CORNER SHOES SPRINGKOIL GREY -7" | D31: NOS | E31: CBERM | F31: 6600 | G31: 10 | H31: 66000 | I31: 0 | K31: 0 | L31: 1700 | M31: 10 | N31: 17000 | O31: 4900 | P31: 10 | Q31: 49000 | R31: LCE | S31: Label,CnrShoe,CentreBand,EdgeTape-10195 | T31: MATRESS
A32: 115 | B32: RML-CS-SPK-GR-8.5 | C32: CORNER SHOES SPRINGKOIL GREY -8.5" | D32: NOS | E32: CBERM | F32: 4400 | G32: 10 | H32: 44000 | I32: 0 | K32: 0 | L32: 100 | M32: 10 | N32: 1000 | O32: 4300 | P32: 10 | Q32: 43000 | R32: LCE | S32: Label,CnrShoe,CentreBand,EdgeTape-10195 | T32: MATRESS
A33: 116 | B33: RML-CS-SPK-MR-10.5 | C33: CORNER SHOES SPRINGKOIL MAROON -10.5" | D33: NOS | E33: CBERM | F33: 1100 | G33: 11.5385 | H33: 12692.3 | I33: 0 | K33: 0 | L33: 200 | M33: 11.5385 | N33: 2307.7 | O33: 900 | P33: 11.5384 | Q33: 10384.6 | R33: LCE | S33: Label,CnrShoe,CentreBand,EdgeTape-10195 | T33: MATRESS
A34: 118 | B34: RML-CS-SPK-MR-6 | C34: CORNER SHOES SPRINGKOIL MAROON -6" | D34: NOS | E34: CBERM | F34: 4100 | G34: 10 | H34: 41000 | I34: 0 | K34: 0 | L34: 300 | M34: 10 | N34: 3000 | O34: 3800 | P34: 10 | Q34: 38000 | R34: LCE | S34: Label,CnrShoe,CentreBand,EdgeTape-10195 | T34: MATRESS
A35: 120 | B35: RML-CS-SPK-MR-7 | C35: CORNER SHOES SPRINGKOIL MAROON -7" | D35: NOS | E35: CBERM | F35: 16500 | G35: 8.6704 | H35: 143061.16 | I35: 0 | K35: 0 | L35: 7500 | M35: 8.6704 | N35: 65028 | O35: 9000 | P35: 8.6704 | Q35: 78033.16 | R35: LCE | S35: Label,CnrShoe,CentreBand,EdgeTape-10195 | T35: MATRESS
A36: 122 | B36: RML-CS-SPK-MR-7.5 | C36: CORNER SHOES SPRINGKOIL MAROON -7.5" | D36: NOS | E36: CBERM | F36: 1145 | G36: 10 | H36: 11450 | I36: 0 | K36: 0 | L36: 0 | N36: 0 | O36: 1145 | P36: 10 | Q36: 11450 | R36: LCE | S36: Label,CnrShoe,CentreBand,EdgeTape-10195 | T36: MATRESS
A37: 124 | B37: RML-CS-SPK-MR-8.5 | C37: CORNER SHOES SPRINGKOIL MAROON -8.5" | D37: NOS | E37: CBERM | F37: 3160 | G37: 10.3345 | H37: 32657.08 | I37: 600 | J37: 10.0477 | K37: 6028.62 | L37: 560 | M37: 10.3034 | N37: 5769.93 | O37: 3200 | P37: 10.2862 | Q37: 32915.77 | R37: LCE | S37: Label,CnrShoe,CentreBand,EdgeTape-10195 | T37: MATRESS
A38: 126 | B38: RML-CS-TRT-7 | C38: CORNER SHOES. TARTANIA-7" | D38: NOS | E38: CBERM | F38: 3500 | G38: 10.2299 | H38: 35804.78 | I38: 0 | K38: 0 | L38: 300 | M38: 10.2299 | N38: 3068.97 | O38: 3200 | P38: 10.2299 | Q38: 32735.81 | R38: LCE | S38: Label,CnrShoe,CentreBand,EdgeTape-10195 | T38: MATRESS
A39: 253 | B39: 100D-RB-FOAM-77X71X25MM | C39: 100D-Rebonded Foam Sheet-77X71X25mm | D39: KGS | E39: CBERM | F39: 0 | H39: 0 | I39: 865.5 | J39: 92 | K39: 79626 | L39: 865.5 | M39: 92 | N39: 79626 | O39: 0 | Q39: 0 | R39: FMREBOND | S39: FOAM REBONDED -10181 | T39: FOAM
A40: 627 | B40: SBLGPS | C40: Knurling Bush | D40: NOS | E40: CBERM | F40: 1220 | G40: 25 | H40: 30500 | I40: 80 | J40: 25 | K40: 2000 | L40: 900 | M40: 25 | N40: 22500 | O40: 400 | P40: 25 | Q40: 10000 | R40: LCE | S40: Label,CnrShoe,CentreBand,EdgeTape-10195 | T40: MATRESS
...

Sheet Item code
A1: S.no | B1: R.no | C1: Date | D1: Item | E1: PS Desc. | F1: PS Usage | G1: PS Category | H1: Process Plan | I1: Uom | J1: Qty | K1: Default For | L1: Wh Code | M1: RM-COST | N1: PRO-RATE
A2: 1 | B2: 1 | C2: 28.03.2024 | D2: SFG-FRBNET-MEM-BOR-72X33X08 | E2: Restonic Hotel Motel Bonnell Euro Top Memory Border 72X33X08 | F2: Standard | G2: Production | H2: TAIL-BORDER | I2: NOS | J2: 1 | K2: MRP&Rollup | L2: CBESFG | M2: 144.148 | N2: 162
A3: 2 | B3: 2 | C3: 28.03.2024 | D3: SFG-FRBNET-MEM-BOR-72X39X08 | E3: Restonic Hotel Motel Bonnell Euro Top Memory Border 72X39X08 | F3: Standard | G3: Production | H3: TAIL-BORDER | I3: NOS | J3: 1 | K3: MRP&Rollup | L3: CBESFG | M3: 150.676 | N3: 170
A4: 3 | B4: 3 | C4: 28.03.2024 | D4: SFG-FRBNET-MEM-BOR-72X45X08 | E4: Restonic Hotel Motel Bonnell Euro Top Memory Border 72X45X08 | F4: Standard | G4: Production | H4: TAIL-BORDER | I4: NOS | J4: 1 | K4: MRP&Rollup | L4: CBESFG | M4: 157.226 | N4: 177
A5: 4 | B5: 4 | C5: 28.03.2024 | D5: SFG-FRBNET-MEM-BOR-72X51X08 | E5: Restonic Hotel Motel Bonnell Euro Top Memory Border 72X51X08 | F5: Standard | G5: Production | H5: TAIL-BORDER | I5: NOS | J5: 1 | K5: MRP&Rollup | L5: CBESFG | M5: 163.776 | N5: 185
A6: 5 | B6: 5 | C6: 28.03.2024 | D6: SFG-FRBNET-MEM-BOR-72X54X08 | E6: Restonic Hotel Motel Bonnell Euro Top Memory Border 72X54X08 | F6: Standard | G6: Production | H6: TAIL-BORDER | I6: NOS | J6: 1 | K6: MRP&Rollup | L6: CBESFG | M6: 167.04 | N6: 188
A7: 6 | B7: 6 | C7: 28.03.2024 | D7: SFG-FRBNET-MEM-BOR-72X57X08 | E7: Restonic Hotel Motel Bonnell Euro Top Memory Border 72X57X08 | F7: Standard | G7: Production | H7: TAIL-BORDER | I7: NOS | J7: 1 | K7: MRP&Rollup | L7: CBESFG | M7: 170.326 | N7: 192
A8: 7 | B8: 7 | C8: 28.03.2024 | D8: SFG-FRBNET-MEM-BOR-72X63X08 | E8: Restonic Hotel Motel Bonnell Euro Top Memory Border 72X63X08 | F8: Standard | G8: Production | H8: TAIL-BORDER | I8: NOS | J8: 1 | K8: MRP&Rollup | L8: CBESFG | M8: 176.876 | N8: 199
A9: 8 | B9: 8 | C9: 28.03.2024 | D9: SFG-FRBNET-MEM-BOR-72X69X08 | E9: Restonic Hotel Motel Bonnell Euro Top Memory Border 72X69X08 | F9: Standard | G9: Production | H9: TAIL-BORDER | I9: NOS | J9: 1 | K9: MRP&Rollup | L9: CBESFG | M9: 183.405 | N9: 207
A10: 9 | B10: 9 | C10: 28.03.2024 | D10: SFG-FRBNET-MEM-BOR-75X33X08 | E10: Restonic Hotel Motel Bonnell Euro Top Memory Border 75X33X08 | F10: Standard | G10: Production | H10: TAIL-BORDER | I10: NOS | J10: 1 | K10: MRP&Rollup | L10: CBESFG | M10: 147.412 | N10: 166
A11: 10 | B11: 10 | C11: 28.03.2024 | D11: SFG-FRBNET-MEM-BOR-75X39X08 | E11: Restonic Hotel Motel Bonnell Euro Top Memory Border 75X39X08 | F11: Standard | G11: Production | H11: TAIL-BORDER | I11: NOS | J11: 1 | K11: MRP&Rollup | L11: CBESFG | M11: 153.962 | N11: 174
A12: 11 | B12: 11 | C12: 28.03.2024 | D12: SFG-FRBNET-MEM-BOR-75X45X08 | E12: Restonic Hotel Motel Bonnell Euro Top Memory Border 75X45X08 | F12: Standard | G12: Production | H12: TAIL-BORDER | I12: NOS | J12: 1 | K12: MRP&Rollup | L12: CBESFG | M12: 160.512 | N12: 181
A13: 12 | B13: 12 | C13: 28.03.2024 | D13: SFG-FRBNET-MEM-BOR-75X51X08 | E13: Restonic Hotel Motel Bonnell Euro Top Memory Border 75X51X08 | F13: Standard | G13: Production | H13: TAIL-BORDER | I13: NOS | J13: 1 | K13: MRP&Rollup | L13: CBESFG | M13: 167.04 | N13: 188
... A41: 40 | B41: 40 | C41: 28.03.2024 | D41: SFG-FRBNET-MEM-BOR-84X69X08 | E41: Restonic Hotel Motel Bonnell Euro Top Memory Border 84X69X08 | F41: Standard | G41: Production | H41: TAIL-BORDER | I41: NOS | J41: 1 | K41: MRP&Rollup | L41: CBESFG | M41: 196.505 | N41: 221

Sheet pro.stru
A1: S.no | B1: R.no | C1: Date | D1: Bom Code/PS.No | E1: PS Desc. | F1: Item | G1: PS Desc. | H1: PS Usage | I1: PS Category | J1: Process Plan | K1: Uom | L1: Qty | M1: Default For | N1: Wh Code | O1: PS Seq | P1: I/O Flag | Q1: Issue Item | R1: Item Desc | S1: Uom | T1: Qty | U1: Std Wh Code | V1: Backflush | W1: Status
A2: 1 | B2: 1 | C2: 28.03.2024 | D2: SFG-FRBNET-MEM-BOR-72X33X08 | E2: Restonic Hotel Motel Bonnell Euro Top Memory Border 72X33X08 | F2: SFG-FRBNET-MEM-BOR-72X33X08 | G2: Restonic Hotel Motel Bonnell Euro Top Memory Border 72X33X08 | H2: Standard | I2: Production | J2: TAIL-BORDER | K2: NOS | L2: 1 | M2: MRP&Rollup | N2: CBESFG | O2: 10 | P2: I | Q2: RM-THRD-QS-TKT40 | R2: THREAD TKT40 210D/3 PLY 10000MTS | S2: MTR | T2: 5.6 | U2: CBEWIP | V2: Backflush | W2: Active
A3: 2 | B3: 1 | C3: 28.03.2024 | D3: SFG-FRBNET-MEM-BOR-72X33X08 | E3: Restonic Hotel Motel Bonnell Euro Top Memory Border 72X33X08 | F3: SFG-FRBNET-MEM-BOR-72X33X08 | G3: Restonic Hotel Motel Bonnell Euro Top Memory Border 72X33X08 | H3: Standard | I3: Production | J3: TAIL-BORDER | K3: NOS | L3: 1 | M3: MRP&Rollup | N3: CBESFG | O3: 20 | P3: I | Q3: HW-CTON-THREAD | R3: COTTON THREAD WHITE 3PLY | S3: MTR | T3: 5 | U3: CBEWIP | V3: Backflush | W3: Active
A4: 3 | B4: 1 | C4: 28.03.2024 | D4: SFG-FRBNET-MEM-BOR-72X33X08 | E4: Restonic Hotel Motel Bonnell Euro Top Memory Border 72X33X08 | F4: SFG-FRBNET-MEM-BOR-72X33X08 | G4: Restonic Hotel Motel Bonnell Euro Top Memory Border 72X33X08 | H4: Standard | I4: Production | J4: TAIL-BORDER | K4: NOS | L4: 1 | M4: MRP&Rollup | N4: CBESFG | O4: 30 | P4: I | Q4: SFG-RTHTMT-BNPK-MEM-BOR-21CM | R4: Hotel Motel Poc ET-8 8MM/16D Pre Foam Memory Border 21 CM Height | S4: MTR | T4: 5.411 | U4: CBESFG | V4: Backflush | W4: Active
A5: 4 | B5: 1 | C5: 28.03.2024 | D5: SFG-FRBNET-MEM-BOR-72X33X08 | E5: Restonic Hotel Motel Bonnell Euro Top Memory Border 72X33X08 | F5: SFG-FRBNET-MEM-BOR-72X33X08 | G5: Restonic Hotel Motel Bonnell Euro Top Memory Border 72X33X08 | H5: Standard | I5: Production | J5: TAIL-BORDER | K5: NOS | L5: 1 | M5: MRP&Rollup | N5: CBESFG | O5: 40 | P5: I | Q5: RMI-HCC-SDE-LBL | R5: HOTEL COMFORT CARE SIDE LABEL (IMPORT) | S5: NOS | T5: 1 | U5: CBEWIP | V5: Backflush | W5: Active
A6: 5 | B6: 1 | C6: 28.03.2024 | D6: SFG-FRBNET-MEM-BOR-72X33X08 | E6: Restonic Hotel Motel Bonnell Euro Top Memory Border 72X33X08 | F6: SFG-FRBNET-MEM-BOR-72X33X08 | G6: Restonic Hotel Motel Bonnell Euro Top Memory Border 72X33X08 | H6: Standard | I6: Production | J6: TAIL-BORDER | K6: NOS | L6: 1 | M6: MRP&Rollup | N6: CBESFG | O6: 50 | P6: I | Q6: RML-MRP-BACK-LBL | R6: MRP BACK LABEL(PLAIN) | S6: NOS | T6: 1 | U6: CBEWIP | V6: Backflush | W6: Active
A7: 6 | B7: 1 | C7: 28.03.2024 | D7: SFG-FRBNET-MEM-BOR-72X33X08 | E7: Restonic Hotel Motel Bonnell Euro Top Memory Border 72X33X08 | F7: SFG-FRBNET-MEM-BOR-72X33X08 | G7: Restonic Hotel Motel Bonnell Euro Top Memory Border 72X33X08 | H7: Standard | I7: Production | J7: TAIL-BORDER | K7: NOS | L7: 1 | M7: MRP&Rollup | N7: CBESFG | O7: 60 | P7: I | Q7: RML-DRN-LBL | R7: DIRECTION LABEL | S7: NOS | T7: 1 | U7: CBEWIP | V7: Backflush | W7: Active
A8: 7 | B8: 1 | C8: 28.03.2024 | D8: SFG-FRBNET-MEM-BOR-72X33X08 | E8: Restonic Hotel Motel Bonnell Euro Top Memory Border 72X33X08 | F8: SFG-FRBNET-MEM-BOR-72X33X08 | G8: Restonic Hotel Motel Bonnell Euro Top Memory Border 72X33X08 | H8: Standard | I8: Production | J8: TAIL-BORDER | K8: NOS | L8: 1 | M8: MRP&Rollup | N8: CBESFG | O8: 70 | P8: I | Q8: SFG-RTHTMT-MEM-HANDLE | R8: Restonic Hotel Motel Memory Handle | S8: MTR | T8: 0.64 | U8: CBESFG | V8: Backflush | W8: Active
A9: 8 | B9: 1 | C9: 28.03.2024 | D9: SFG-FRBNET-MEM-BOR-72X33X08 | E9: Restonic Hotel Motel Bonnell Euro Top Memory Border 72X33X08 | F9: SFG-FRBNET-MEM-BOR-72X33X08 | G9: Restonic Hotel Motel Bonnell Euro Top Memory Border 72X33X08 | H9: Standard | I9: Production | J9: TAIL-BORDER | K9: NOS | L9: 1 | M9: MRP&Rollup | N9: CBESFG | O9: 80 | P9: I | Q9: RMI-BREATHER-GOLD | R9: BREATHER SET GOLD ROUND | S9: SET | T9: 2 | U9: CBEWIP | V9: Backflush | W9: Active
A10: 9 | B10: 2 | C10: 28.03.2024 | D10: SFG-FRBNET-MEM-BOR-72X39X08 | E10: Restonic Hotel Motel Bonnell Euro Top Memory Border 72X39X08 | F10: SFG-FRBNET-MEM-BOR-72X39X08 | G10: Restonic Hotel Motel Bonnell Euro Top Memory Border 72X39X08 | H10: Standard | I10: Production | J10: TAIL-BORDER | K10: NOS | L10: 1 | M10: MRP&Rollup | N10: CBESFG | O10: 10 | P10: I | Q10: RM-THRD-QS-TKT40 | R10: THREAD TKT40 210D/3 PLY 10000MTS | S10: MTR | T10: 5.6 | U10: CBEWIP | V10: Backflush | W10: Active
A11: 10 | B11: 2 | C11: 28.03.2024 | D11: SFG-FRBNET-MEM-BOR-72X39X08 | E11: Restonic Hotel Motel Bonnell Euro Top Memory Border 72X39X08 | F11: SFG-FRBNET-MEM-BOR-72X39X08 | G11: Restonic Hotel Motel Bonnell Euro Top Memory Border 72X39X08 | H11: Standard | I11: Production | J11: TAIL-BORDER | K11: NOS | L11: 1 | M11: MRP&Rollup | N11: CBESFG | O11: 20 | P11: I | Q11: HW-CTON-THREAD | R11: COTTON THREAD WHITE 3PLY | S11: MTR | T11: 5 | U11: CBEWIP | V11: Backflush | W11: Active
A12: 11 | B12: 2 | C12: 28.03.2024 | D12: SFG-FRBNET-MEM-BOR-72X39X08 | E12: Restonic Hotel Motel Bonnell Euro Top Memory Border 72X39X08 | F12: SFG-FRBNET-MEM-BOR-72X39X08 | G12: Restonic Hotel Motel Bonnell Euro Top Memory Border 72X39X08 | H12: Standard | I12: Production | J12: TAIL-BORDER | K12: NOS | L12: 1 | M12: MRP&Rollup | N12: CBESFG | O12: 30 | P12: I | Q12: SFG-RTHTMT-BNPK-MEM-BOR-21CM | R12: Hotel Motel Poc ET-8 8MM/16D Pre Foam Memory Border 21 CM Height | S12: MTR | T12: 5.715 | U12: CBESFG | V12: Backflush | W12: Active
A13: 12 | B13: 2 | C13: 28.03.2024 | D13: SFG-FRBNET-MEM-BOR-72X39X08 | E13: Restonic Hotel Motel Bonnell Euro Top Memory Border 72X39X08 | F13: SFG-FRBNET-MEM-BOR-72X39X08 | G13: Restonic Hotel Motel Bonnell Euro Top Memory Border 72X39X08 | H13: Standard | I13: Production | J13: TAIL-BORDER | K13: NOS | L13: 1 | M13: MRP&Rollup | N13: CBESFG | O13: 40 | P13: I | Q13: RMI-HCC-SDE-LBL | R13: HOTEL COMFORT CARE SIDE LABEL (IMPORT) | S13: NOS | T13: 1 | U13: CBEWIP | V13: Backflush | W13: Active
... A321: 320 | B321: 40 | C321: 28.03.2024 | D321: SFG-FRBNET-MEM-BOR-84X69X08 | E321: Restonic Hotel Motel Bonnell Euro Top Memory Border 84X69X08 | F321: SFG-FRBNET-MEM-BOR-84X69X08 | G321: Restonic Hotel Motel Bonnell Euro Top Memory Border 84X69X08 | H321: Standard | I321: Production | J321: TAIL-BORDER | K321: NOS | L321: 1 | M321: MRP&Rollup | N321: CBESFG | O321: 80 | P321: I | Q321: RMI-BREATHER-GOLD | R321: BREATHER SET GOLD ROUND | S321: SET | T321: 2 | U321: CBEWIP | V321: Backflush | W321: Active
