Workbook

Sheet Matt-FON Et
A1: S.NO | B1: ITEM CODE | C1: ITEM DESC
A2: 1 | B2: RTHTMTBNET72X33X06 | C2: Peps Restonic Hotel Motel Bonnell Euro Top 72X33X06
A3: 2 | B3: RTHTMTBNET72X39X06 | C3: Peps Restonic Hotel Motel Bonnell Euro Top 72X39X06
A4: 3 | B4: RTHTMTBNET72X45X06 | C4: Peps Restonic Hotel Motel Bonnell Euro Top 72X45X06
A5: 4 | B5: RTHTMTBNET72X51X06 | C5: Peps Restonic Hotel Motel Bonnell Euro Top 72X51X06
A6: 5 | B6: RTHTMTBNET72X54X06 | C6: Peps Restonic Hotel Motel Bonnell Euro Top 72X54X06
A7: 6 | B7: RTHTMTBNET72X57X06 | C7: Peps Restonic Hotel Motel Bonnell Euro Top 72X57X06
A8: 7 | B8: RTHTMTBNET72X63X06 | C8: Peps Restonic Hotel Motel Bonnell Euro Top 72X63X06
A9: 8 | B9: RTHTMTBNET72X69X06 | C9: Peps Restonic Hotel Motel Bonnell Euro Top 72X69X06
A10: 9 | B10: RTHTMTBNET75X33X06 | C10: Peps Restonic Hotel Motel Bonnell Euro Top 75X33X06
A11: 10 | B11: RTHTMTBNET75X39X06 | C11: Peps Restonic Hotel Motel Bonnell Euro Top 75X39X06
A12: 11 | B12: RTHTMTBNET75X45X06 | C12: Peps Restonic Hotel Motel Bonnell Euro Top 75X45X06
A13: 12 | B13: RTHTMTBNET75X51X06 | C13: Peps Restonic Hotel Motel Bonnell Euro Top 75X51X06
... A121: 120 | B121: RTHTMTBNET84X69X10 | C121: Peps Restonic Hotel Motel Bonnell Euro Top 84X69X10

Sheet Manual
B2: 72X30 | C2: RM-NWN-70GSMX6INCH | D2: 0.051 | F2: RML-NWN-70GSMX76" | G2: 0.104
B3: 72X33 | C3: RM-NWN-70GSMX6INCH | D3: 0.052 | F3: RML-NWN-70GSMX76" | G3: 0.113
B4: 72X36 | C4: RM-NWN-70GSMX6INCH | D4: 0.054 | F4: RML-NWN-70GSMX76" | G4: 0.124
B5: 72X39 | C5: RM-NWN-70GSMX6INCH | D5: 0.056 | F5: RML-NWN-70GSMX76" | G5: 0.133
B6: 72X42 | C6: RM-NWN-70GSMX6INCH | D6: 0.057 | F6: RML-NWN-70GSMX76" | G6: 0.144
B7: 72X45 | C7: RM-NWN-70GSMX6INCH | D7: 0.058 | F7: RML-NWN-70GSMX76" | G7: 0.157
B8: 72X48 | C8: RM-NWN-70GSMX6INCH | D8: 0.06 | F8: RML-NWN-70GSMX76" | G8: 0.169
B9: 72X51 | C9: RM-NWN-70GSMX6INCH | D9: 0.061 | F9: RML-NWN-70GSMX76" | G9: 0.173
B10: 72X54 | C10: RM-NWN-70GSMX6INCH | D10: 0.063 | F10: RML-NWN-70GSMX76" | G10: 0.185
B11: 72X57 | C11: RM-NWN-70GSMX6INCH | D11: 0.065 | F11: RML-NWN-70GSMX76" | G11: 0.196
B12: 72X60 | C12: RM-NWN-70GSMX6INCH | D12: 0.067 | F12: RML-NWN-70GSMX76" | G12: 0.209
B13: 72X63 | C13: RM-NWN-70GSMX6INCH | D13: 0.068 | F13: RML-NWN-70GSMX76" | G13: 0.219
... B80: 84X72 | C80: RM-NWN-70GSMX6INCH | D80: 0.079 | F80: RML-NWN-70GSMX79" | G80: 0.304

Sheet Workings
A1: S.no | B1: R.no | C1: VARIETIES | D1: Col | E1: Matt item Code | F1: REF1 | G1: REF2 | H1: REF3 | I1: REF4 | J1: REF5 | K1: LENGTH | L1: WIDTH | M1: HEIGHT | N1: Bom Code/PS.No | P1: Consum | Q1: CTN THREAD | S1: PS Desc. | T1: Item | W1: Item Desc | X1: PS Usage | Y1: PS Category | Z1: Process Plan | AA1: Uom | AB1: Qty | AC1: Default For | AD1: Wh Code | AE1: PS Seq | AF1: I/O Flag | AG1: Issue Item | AH1: Item Desc | AI1: Uom | AJ1: Qty | AK1: Std Wh Code | AL1: Backflush | AM1: Status | AN1: CONV | AO1: RATE | AP1: SUB.TOT | AQ1: TOT | AR1: ROUNDUP | AS1: Rm-cost | AT1: PRO-RATE | AU1: Wastage | AV1: DL | AW1: MOH | AX1: Dep | AY1: Standard Cost | AZ1: R-UP | BA1: PRO-RATE
A2: 1 | B2: 1 | C2: ET-COVER | D2: =MID(E2,9,2) -> PT | E2: RTHTMTBNPT72X33X10 | F2: =LEFT(E2,MIN(FIND({0,1,2,3,4,5,6,7,8,9},E2&"0123456789"))-1) -> RTHTMTBNPT | G2: =SUBSTITUTE(E2,F2,"") -> 72X33X10 | H2: =IFERROR(LEFT(G2,FIND("-",G2)-1),G2) -> 72X33X10 | I2: =SEARCH("X",H2) -> 3 | J2: =SEARCH("X",H2,I2+1) -> 6 | K2: =LEFT(G2,SEARCH("x",G2)-1) -> 72 | L2: =MID(H2,I2+1,J2-I2-1) -> 33 | M2: =MID(H2,J2+1,20) -> 10 | N2: ="SFG-FRBNPK-ET-CVR-"&K2&"X"&L2&"X"&M2 -> SFG-FRBNPK-ET-CVR-72X33X10 | P2: =ROUND(((((K2+L2+K2+L2)+3)*0.0254)*5.3196),3) -> 28.78 | Q2: 0 | R2: =P2+Q2 -> 28.78 | S2: ="Restonic Hotel Motel ET Cover "&K2&"X"&L2&"X"&M2 -> Restonic Hotel Motel ET Cover 72X33X10 | T2: =N2 -> SFG-FRBNPK-ET-CVR-72X33X10 | U2: =T2=N2 -> TRUE | V2: =S2=W2 -> TRUE | W2: =S2 -> Restonic Hotel Motel ET Cover 72X33X10 | X2: Standard | Y2: Production | Z2: TAIL-ET-PT | AA2: NOS | AB2: 1 | AC2: MRP&Rollup | AD2: CBESFG | AE2: 10 | AF2: I | AG2: RM-THRD-QS-TKT40 | AH2: THREAD TKT40 210D/3 PLY 10000MTS | AI2: MTR | AJ2: =R2 -> 28.78 | AK2: CBEWIP | AL2: Backflush | AM2: Active | AN2: =AJ2/10000 -> 0.002878 | AO2: =VLOOKUP(AG2,'RM-cost - feb-24'!B:P,15,0) -> 231.1423 | AP2: =AO2*AN2 -> 0.66522754 | AQ2: =SUM(AP2:AP6) -> 125.51946 | AR2: =ROUND(AQ2,0) -> 126 | AS2: =AR2 -> 126 | AT2: =+AS2+AY2 -> 141.59237 | AU2: =+SUM(((AS2*3%*18%))) -> 0.6804 | AV2: =+SUM(((AS2*14.33%*53%))) -> 9.569574 | AW2: =+SUM(((AS2*5.92%*53%))) -> 3.953376 | AX2: =+SUM(((AS2*2.08%*53%))) -> 1.389024 | AY2: =SUM(AU2:AX6) -> 15.592374 | AZ2: =ROUNDUP(AT2,0) -> 142 | BA2: =AZ2 -> 142
A3: 2 | B3: =B2 -> 1 | C3: =C2 -> ET-COVER | D3: =MID(E3,9,2) -> PT | E3: =E2 -> RTHTMTBNPT72X33X10 | F3: =F2 -> RTHTMTBNPT | G3: =G2 -> 72X33X10 | H3: =H2 -> 72X33X10 | I3: =I2 -> 3 | J3: =J2 -> 6 | K3: =K2 -> 72 | L3: =L2 -> 33 | M3: =M2 -> 10 | N3: ="SFG-FRBNPK-ET-CVR-"&K3&"X"&L3&"X"&M3 -> SFG-FRBNPK-ET-CVR-72X33X10 | O3: =K3*L3/144 -> 16.5 | P3: =ROUNDUP((((K3*L3/144)*0.003)),3) -> 0.05 | S3: ="Restonic Hotel Motel ET Cover "&K3&"X"&L3&"X"&M3 -> Restonic Hotel Motel ET Cover 72X33X10 | T3: =T2 -> SFG-FRBNPK-ET-CVR-72X33X10 | U3: =T3=N3 -> TRUE | V3: =S3=W3 -> TRUE | W3: =W2 -> Restonic Hotel Motel ET Cover 72X33X10 | X3: Standard | Y3: Production | Z3: TAIL-ET-PT | AA3: NOS | AB3: 1 | AC3: MRP&Rollup | AD3: CBESFG | AE3: 20 | AF3: I | AG3: RM-NWN-70GSMX6INCH | AH3: NON WOVEN FABRIC 70GSMX6" | AI3: KGS | AJ3: 0.052 | AK3: CBEWIP | AL3: Backflush | AM3: Active | AN3: =AJ3 -> 0.052 | AO3: =VLOOKUP(AG3,'RM-cost - feb-24'!B:P,15,0) -> 113.786 | AP3: =AO3*AN3 -> 5.916872 | AS3: =AS2 -> 126
A4: 3 | B4: =B3 -> 1 | C4: =C3 -> ET-COVER | D4: =MID(E4,9,2) -> PT | E4: =E3 -> RTHTMTBNPT72X33X10 | F4: =F3 -> RTHTMTBNPT | G4: =G3 -> 72X33X10 | H4: =H3 -> 72X33X10 | I4: =I3 -> 3 | J4: =J3 -> 6 | K4: =K3 -> 72 | L4: =L3 -> 33 | M4: =M3 -> 10 | N4: ="SFG-FRBNPK-ET-CVR-"&K4&"X"&L4&"X"&M4 -> SFG-FRBNPK-ET-CVR-72X33X10 | P4: =ROUNDUP((((K4*L4/144)*0.00692)),3) -> 0.115 | Q4: =P4=AJ4 -> FALSE | S4: ="Restonic Hotel Motel ET Cover "&K4&"X"&L4&"X"&M4 -> Restonic Hotel Motel ET Cover 72X33X10 | T4: =T3 -> SFG-FRBNPK-ET-CVR-72X33X10 | U4: =T4=N4 -> TRUE | V4: =S4=W4 -> TRUE | W4: =W3 -> Restonic Hotel Motel ET Cover 72X33X10 | X4: Standard | Y4: Production | Z4: TAIL-ET-PT | AA4: NOS | AB4: 1 | AC4: MRP&Rollup | AD4: CBESFG | AE4: 30 | AF4: I | AG4: RML-NWN-70GSMX76" | AH4: NON WOVEN FABRIC WHITE 70 GSM 76 INCH | AI4: KGS | AJ4: 0.113 | AK4: CBEWIP | AL4: Backflush | AM4: Active | AN4: =AJ4 -> 0.113 | AO4: =VLOOKUP(AG4,'RM-cost - feb-24'!B:P,15,0) -> 112.8872 | AP4: =AO4*AN4 -> 12.756254 | AS4: =AS3 -> 126
A5: 4 | B5: =B4 -> 1 | C5: =C4 -> ET-COVER | D5: =MID(E5,9,2) -> PT | E5: =E4 -> RTHTMTBNPT72X33X10 | F5: =F4 -> RTHTMTBNPT | G5: =G4 -> 72X33X10 | H5: =H4 -> 72X33X10 | I5: =I4 -> 3 | J5: =J4 -> 6 | K5: =K4 -> 72 | L5: =L4 -> 33 | M5: =M4 -> 10 | N5: ="SFG-FRBNPK-ET-CVR-"&K5&"X"&L5&"X"&M5 -> SFG-FRBNPK-ET-CVR-72X33X10 | P5: =ROUND(((((K5+L5+K5+L5)+3))*0.0254),3) -> 5.41 | Q5: =P5=AJ5 -> TRUE | S5: ="Restonic Hotel Motel ET Cover "&K5&"X"&L5&"X"&M5 -> Restonic Hotel Motel ET Cover 72X33X10 | T5: =T4 -> SFG-FRBNPK-ET-CVR-72X33X10 | U5: =T5=N5 -> TRUE | V5: =S5=W5 -> TRUE | W5: =W4 -> Restonic Hotel Motel ET Cover 72X33X10 | X5: Standard | Y5: Production | Z5: TAIL-ET-PT | AA5: NOS | AB5: 1 | AC5: MRP&Rollup | AD5: CBESFG | AE5: 40 | AF5: I | AG5: SFG-RTHTMT-BNPK-ETBOR-11CM | AH5: Hotel Motel Poc ET-10 & 12 8MM/16D Pre Foam Border 11 CM Height | AI5: MTR | AJ5: =P5 -> 5.41 | AK5: CBESFG | AL5: Backflush | AM5: Active | AN5: =AJ5 -> 5.41 | AO5: =VLOOKUP(AG5,'SFG-rate rm - feb-24'!A:B,2,0) -> 19.60538 | AP5: =AO5*AN5 -> 106.06511 | AS5: =AS4 -> 126
A6: 5 | B6: =B5 -> 1 | C6: =C5 -> ET-COVER | D6: =MID(E6,9,2) -> PT | E6: =E5 -> RTHTMTBNPT72X33X10 | F6: =F5 -> RTHTMTBNPT | G6: =G5 -> 72X33X10 | H6: =H5 -> 72X33X10 | I6: =I5 -> 3 | J6: =J5 -> 6 | K6: =K5 -> 72 | L6: =L5 -> 33 | M6: =M5 -> 10 | N6: ="SFG-FRBNPK-ET-CVR-"&K6&"X"&L6&"X"&M6 -> SFG-FRBNPK-ET-CVR-72X33X10 | P6: 10 | Q6: =P6=AJ6 -> TRUE | S6: ="Restonic Hotel Motel ET Cover "&K6&"X"&L6&"X"&M6 -> Restonic Hotel Motel ET Cover 72X33X10 | T6: =T5 -> SFG-FRBNPK-ET-CVR-72X33X10 | U6: =T6=N6 -> TRUE | V6: =S6=W6 -> TRUE | W6: =W5 -> Restonic Hotel Motel ET Cover 72X33X10 | X6: Standard | Y6: Production | Z6: TAIL-ET-PT | AA6: NOS | AB6: 1 | AC6: MRP&Rollup | AD6: CBESFG | AE6: 50 | AF6: I | AG6: HW-CTON-THREAD | AH6: COTTON THREAD WHITE 3PLY | AI6: MTR | AJ6: =P6 -> 10 | AK6: CBEWIP | AL6: Backflush | AM6: Active | AN6: =AJ6/5000 -> 0.002 | AO6: =VLOOKUP(AG6,'RM-cost - feb-24'!B:P,15,0) -> 58 | AP6: =AO6*AN6 -> 0.116 | AS6: =AS5 -> 126
A8: 1 | B8: 2 | C8: ET-COVER | D8: =MID(E8,9,2) -> PT | E8: RTHTMTBNPT72X39X10 | F8: =LEFT(E8,MIN(FIND({0,1,2,3,4,5,6,7,8,9},E8&"0123456789"))-1) -> RTHTMTBNPT | G8: =SUBSTITUTE(E8,F8,"") -> 72X39X10 | H8: =IFERROR(LEFT(G8,FIND("-",G8)-1),G8) -> 72X39X10 | I8: =SEARCH("X",H8) -> 3 | J8: =SEARCH("X",H8,I8+1) -> 6 | K8: =LEFT(G8,SEARCH("x",G8)-1) -> 72 | L8: =MID(H8,I8+1,J8-I8-1) -> 39 | M8: =MID(H8,J8+1,20) -> 10 | N8: ="SFG-FRBNPK-ET-CVR-"&K8&"X"&L8&"X"&M8 -> SFG-FRBNPK-ET-CVR-72X39X10 | P8: =ROUND(((((K8+L8+K8+L8)+3)*0.0254)*5.3196),3) -> 30.402 | Q8: 0 | R8: =P8+Q8 -> 30.402 | S8: ="Restonic Hotel Motel ET Cover "&K8&"X"&L8&"X"&M8 -> Restonic Hotel Motel ET Cover 72X39X10 | T8: =N8 -> SFG-FRBNPK-ET-CVR-72X39X10 | U8: =T8=N8 -> TRUE | V8: =S8=W8 -> TRUE | W8: =S8 -> Restonic Hotel Motel ET Cover 72X39X10 | X8: Standard | Y8: Production | Z8: TAIL-ET-PT | AA8: NOS | AB8: 1 | AC8: MRP&Rollup | AD8: CBESFG | AE8: 10 | AF8: I | AG8: RM-THRD-QS-TKT40 | AH8: THREAD TKT40 210D/3 PLY 10000MTS | AI8: MTR | AJ8: =R8 -> 30.402 | AK8: CBEWIP | AL8: Backflush | AM8: Active | AN8: =AJ8/10000 -> 0.0030402 | AO8: =VLOOKUP(AG8,'RM-cost - feb-24'!B:P,15,0) -> 231.1423 | AP8: =AO8*AN8 -> 0.70271882 | AQ8: =SUM(AP8:AP12) -> 134.24948 | AR8: =ROUND(AQ8,0) -> 134 | AS8: =AR8 -> 134 | AT8: =+AS8+AY8 -> 150.58237 | AU8: =+SUM(((AS8*3%*18%))) -> 0.7236 | AV8: =+SUM(((AS8*14.33%*53%))) -> 10.177166 | AW8: =+SUM(((AS8*5.92%*53%))) -> 4.204384 | AX8: =+SUM(((AS8*2.08%*53%))) -> 1.477216 | AY8: =SUM(AU8:AX12) -> 16.582366 | AZ8: =ROUNDUP(AT8,0) -> 151 | BA8: =AZ8 -> 151
A9: 2 | B9: =B8 -> 2 | C9: =C8 -> ET-COVER | D9: =MID(E9,9,2) -> PT | E9: =E8 -> RTHTMTBNPT72X39X10 | F9: =F8 -> RTHTMTBNPT | G9: =G8 -> 72X39X10 | H9: =H8 -> 72X39X10 | I9: =I8 -> 3 | J9: =J8 -> 6 | K9: =K8 -> 72 | L9: =L8 -> 39 | M9: =M8 -> 10 | N9: ="SFG-FRBNPK-ET-CVR-"&K9&"X"&L9&"X"&M9 -> SFG-FRBNPK-ET-CVR-72X39X10 | O9: =K9*L9/144 -> 19.5 | P9: =ROUNDUP((((K9*L9/144)*0.003)),3) -> 0.059 | S9: ="Restonic Hotel Motel ET Cover "&K9&"X"&L9&"X"&M9 -> Restonic Hotel Motel ET Cover 72X39X10 | T9: =T8 -> SFG-FRBNPK-ET-CVR-72X39X10 | U9: =T9=N9 -> TRUE | V9: =S9=W9 -> TRUE | W9: =W8 -> Restonic Hotel Motel ET Cover 72X39X10 | X9: Standard | Y9: Production | Z9: TAIL-ET-PT | AA9: NOS | AB9: 1 | AC9: MRP&Rollup | AD9: CBESFG | AE9: 20 | AF9: I | AG9: RM-NWN-70GSMX6INCH | AH9: NON WOVEN FABRIC 70GSMX6" | AI9: KGS | AJ9: 0.056 | AK9: CBEWIP | AL9: Backflush | AM9: Active | AN9: =AJ9 -> 0.056 | AO9: =VLOOKUP(AG9,'RM-cost - feb-24'!B:P,15,0) -> 113.786 | AP9: =AO9*AN9 -> 6.372016 | AS9: =AS8 -> 134
A10: 3 | B10: =B9 -> 2 | C10: =C9 -> ET-COVER | D10: =MID(E10,9,2) -> PT | E10: =E9 -> RTHTMTBNPT72X39X10 | F10: =F9 -> RTHTMTBNPT | G10: =G9 -> 72X39X10 | H10: =H9 -> 72X39X10 | I10: =I9 -> 3 | J10: =J9 -> 6 | K10: =K9 -> 72 | L10: =L9 -> 39 | M10: =M9 -> 10 | N10: ="SFG-FRBNPK-ET-CVR-"&K10&"X"&L10&"X"&M10 -> SFG-FRBNPK-ET-CVR-72X39X10 | P10: =ROUNDUP((((K10*L10/144)*0.00692)),3) -> 0.135 | Q10: =P10=AJ10 -> FALSE | S10: ="Restonic Hotel Motel ET Cover "&K10&"X"&L10&"X"&M10 -> Restonic Hotel Motel ET Cover 72X39X10 | T10: =T9 -> SFG-FRBNPK-ET-CVR-72X39X10 | U10: =T10=N10 -> TRUE | V10: =S10=W10 -> TRUE | W10: =W9 -> Restonic Hotel Motel ET Cover 72X39X10 | X10: Standard | Y10: Production | Z10: TAIL-ET-PT | AA10: NOS | AB10: 1 | AC10: MRP&Rollup | AD10: CBESFG | AE10: 30 | AF10: I | AG10: RML-NWN-70GSMX76" | AH10: NON WOVEN FABRIC WHITE 70 GSM 76 INCH | AI10: KGS | AJ10: 0.133 | AK10: CBEWIP | AL10: Backflush | AM10: Active | AN10: =AJ10 -> 0.133 | AO10: =VLOOKUP(AG10,'RM-cost - feb-24'!B:P,15,0) -> 112.8872 | AP10: =AO10*AN10 -> 15.013998 | AS10: =AS9 -> 134
A11: 4 | B11: =B10 -> 2 | C11: =C10 -> ET-COVER | D11: =MID(E11,9,2) -> PT | E11: =E10 -> RTHTMTBNPT72X39X10 | F11: =F10 -> RTHTMTBNPT | G11: =G10 -> 72X39X10 | H11: =H10 -> 72X39X10 | I11: =I10 -> 3 | J11: =J10 -> 6 | K11: =K10 -> 72 | L11: =L10 -> 39 | M11: =M10 -> 10 | N11: ="SFG-FRBNPK-ET-CVR-"&K11&"X"&L11&"X"&M11 -> SFG-FRBNPK-ET-CVR-72X39X10 | P11: =ROUND(((((K11+L11+K11+L11)+3))*0.0254),3) -> 5.715 | Q11: =P11=AJ11 -> TRUE | S11: ="Restonic Hotel Motel ET Cover "&K11&"X"&L11&"X"&M11 -> Restonic Hotel Motel ET Cover 72X39X10 | T11: =T10 -> SFG-FRBNPK-ET-CVR-72X39X10 | U11: =T11=N11 -> TRUE | V11: =S11=W11 -> TRUE | W11: =W10 -> Restonic Hotel Motel ET Cover 72X39X10 | X11: Standard | Y11: Production | Z11: TAIL-ET-PT | AA11: NOS | AB11: 1 | AC11: MRP&Rollup | AD11: CBESFG | AE11: 40 | AF11: I | AG11: SFG-RTHTMT-BNPK-ETBOR-11CM | AH11: Hotel Motel Poc ET-10 & 12 8MM/16D Pre Foam Border 11 CM Height | AI11: MTR | AJ11: =P11 -> 5.715 | AK11: CBESFG | AL11: Backflush | AM11: Active | AN11: =AJ11 -> 5.715 | AO11: =VLOOKUP(AG11,'SFG-rate rm - feb-24'!A:B,2,0) -> 19.60538 | AP11: =AO11*AN11 -> 112.04475 | AS11: =AS10 -> 134
A12: 5 | B12: =B11 -> 2 | C12: =C11 -> ET-COVER | D12: =MID(E12,9,2) -> PT | E12: =E11 -> RTHTMTBNPT72X39X10 | F12: =F11 -> RTHTMTBNPT | G12: =G11 -> 72X39X10 | H12: =H11 -> 72X39X10 | I12: =I11 -> 3 | J12: =J11 -> 6 | K12: =K11 -> 72 | L12: =L11 -> 39 | M12: =M11 -> 10 | N12: ="SFG-FRBNPK-ET-CVR-"&K12&"X"&L12&"X"&M12 -> SFG-FRBNPK-ET-CVR-72X39X10 | P12: 10 | Q12: =P12=AJ12 -> TRUE | S12: ="Restonic Hotel Motel ET Cover "&K12&"X"&L12&"X"&M12 -> Restonic Hotel Motel ET Cover 72X39X10 | T12: =T11 -> SFG-FRBNPK-ET-CVR-72X39X10 | U12: =T12=N12 -> TRUE | V12: =S12=W12 -> TRUE | W12: =W11 -> Restonic Hotel Motel ET Cover 72X39X10 | X12: Standard | Y12: Production | Z12: TAIL-ET-PT | AA12: NOS | AB12: 1 | AC12: MRP&Rollup | AD12: CBESFG | AE12: 50 | AF12: I | AG12: HW-CTON-THREAD | AH12: COTTON THREAD WHITE 3PLY | AI12: MTR | AJ12: =P12 -> 10 | AK12: CBEWIP | AL12: Backflush | AM12: Active | AN12: =AJ12/5000 -> 0.002 | AO12: =VLOOKUP(AG12,'RM-cost - feb-24'!B:P,15,0) -> 58 | AP12: =AO12*AN12 -> 0.116 | AS12: =AS11 -> 134
A14: 1 | B14: 3 | C14: ET-COVER | D14: =MID(E14,9,2) -> PT | E14: RTHTMTBNPT72X45X10 | F14: =LEFT(E14,MIN(FIND({0,1,2,3,4,5,6,7,8,9},E14&"0123456789"))-1) -> RTHTMTBNPT | G14: =SUBSTITUTE(E14,F14,"") -> 72X45X10 | H14: =IFERROR(LEFT(G14,FIND("-",G14)-1),G14) -> 72X45X10 | I14: =SEARCH("X",H14) -> 3 | J14: =SEARCH("X",H14,I14+1) -> 6 | K14: =LEFT(G14,SEARCH("x",G14)-1) -> 72 | L14: =MID(H14,I14+1,J14-I14-1) -> 45 | M14: =MID(H14,J14+1,20) -> 10 | N14: ="SFG-FRBNPK-ET-CVR-"&K14&"X"&L14&"X"&M14 -> SFG-FRBNPK-ET-CVR-72X45X10 | P14: =ROUND(((((K14+L14+K14+L14)+3)*0.0254)*5.3196),3) -> 32.023 | Q14: 0 | R14: =P14+Q14 -> 32.023 | S14: ="Restonic Hotel Motel ET Cover "&K14&"X"&L14&"X"&M14 -> Restonic Hotel Motel ET Cover 72X45X10 | T14: =N14 -> SFG-FRBNPK-ET-CVR-72X45X10 | U14: =T14=N14 -> TRUE | V14: =S14=W14 -> TRUE | W14: =S14 -> Restonic Hotel Motel ET Cover 72X45X10 | X14: Standard | Y14: Production | Z14: TAIL-ET-PT | AA14: NOS | AB14: 1 | AC14: MRP&Rollup | AD14: CBESFG | AE14: 10 | AF14: I | AG14: RM-THRD-QS-TKT40 | AH14: THREAD TKT40 210D/3 PLY 10000MTS | AI14: MTR | AJ14: =R14 -> 32.023 | AK14: CBEWIP | AL14: Backflush | AM14: Active | AN14: =AJ14/10000 -> 0.0032023 | AO14: =VLOOKUP(AG14,'RM-cost - feb-24'!B:P,15,0) -> 231.1423 | AP14: =AO14*AN14 -> 0.74018699 | AQ14: =SUM(AP14:AP18) -> 143.20345 | AR14: =ROUND(AQ14,0) -> 143 | AS14: =AR14 -> 143 | AT14: =+AS14+AY14 -> 160.69611 | AU14: =+SUM(((AS14*3%*18%))) -> 0.7722 | AV14: =+SUM(((AS14*14.33%*53%))) -> 10.860707 | AW14: =+SUM(((AS14*5.92%*53%))) -> 4.486768 | AX14: =+SUM(((AS14*2.08%*53%))) -> 1.576432 | AY14: =SUM(AU14:AX18) -> 17.696107 | AZ14: =ROUNDUP(AT14,0) -> 161 | BA14: =AZ14 -> 161
A15: 2 | B15: =B14 -> 3 | C15: =C14 -> ET-COVER | D15: =MID(E15,9,2) -> PT | E15: =E14 -> RTHTMTBNPT72X45X10 | F15: =F14 -> RTHTMTBNPT | G15: =G14 -> 72X45X10 | H15: =H14 -> 72X45X10 | I15: =I14 -> 3 | J15: =J14 -> 6 | K15: =K14 -> 72 | L15: =L14 -> 45 | M15: =M14 -> 10 | N15: ="SFG-FRBNPK-ET-CVR-"&K15&"X"&L15&"X"&M15 -> SFG-FRBNPK-ET-CVR-72X45X10 | O15: =K15*L15/144 -> 22.5 | P15: =ROUNDUP((((K15*L15/144)*0.003)),3) -> 0.068 | S15: ="Restonic Hotel Motel ET Cover "&K15&"X"&L15&"X"&M15 -> Restonic Hotel Motel ET Cover 72X45X10 | T15: =T14 -> SFG-FRBNPK-ET-CVR-72X45X10 | U15: =T15=N15 -> TRUE | V15: =S15=W15 -> TRUE | W15: =W14 -> Restonic Hotel Motel ET Cover 72X45X10 | X15: Standard | Y15: Production | Z15: TAIL-ET-PT | AA15: NOS | AB15: 1 | AC15: MRP&Rollup | AD15: CBESFG | AE15: 20 | AF15: I | AG15: RM-NWN-70GSMX6INCH | AH15: NON WOVEN FABRIC 70GSMX6" | AI15: KGS | AJ15: 0.058 | AK15: CBEWIP | AL15: Backflush | AM15: Active | AN15: =AJ15 -> 0.058 | AO15: =VLOOKUP(AG15,'RM-cost - feb-24'!B:P,15,0) -> 113.786 | AP15: =AO15*AN15 -> 6.599588 | AS15: =AS14 -> 143
A16: 3 | B16: =B15 -> 3 | C16: =C15 -> ET-COVER | D16: =MID(E16,9,2) -> PT | E16: =E15 -> RTHTMTBNPT72X45X10 | F16: =F15 -> RTHTMTBNPT | G16: =G15 -> 72X45X10 | H16: =H15 -> 72X45X10 | I16: =I15 -> 3 | J16: =J15 -> 6 | K16: =K15 -> 72 | L16: =L15 -> 45 | M16: =M15 -> 10 | N16: ="SFG-FRBNPK-ET-CVR-"&K16&"X"&L16&"X"&M16 -> SFG-FRBNPK-ET-CVR-72X45X10 | P16: =ROUNDUP((((K16*L16/144)*0.00692)),3) -> 0.156 | Q16: =P16=AJ16 -> FALSE | S16: ="Restonic Hotel Motel ET Cover "&K16&"X"&L16&"X"&M16 -> Restonic Hotel Motel ET Cover 72X45X10 | T16: =T15 -> SFG-FRBNPK-ET-CVR-72X45X10 | U16: =T16=N16 -> TRUE | V16: =S16=W16 -> TRUE | W16: =W15 -> Restonic Hotel Motel ET Cover 72X45X10 | X16: Standard | Y16: Production | Z16: TAIL-ET-PT | AA16: NOS | AB16: 1 | AC16: MRP&Rollup | AD16: CBESFG | AE16: 30 | AF16: I | AG16: RML-NWN-70GSMX76" | AH16: NON WOVEN FABRIC WHITE 70 GSM 76 INCH | AI16: KGS | AJ16: 0.157 | AK16: CBEWIP | AL16: Backflush | AM16: Active | AN16: =AJ16 -> 0.157 | AO16: =VLOOKUP(AG16,'RM-cost - feb-24'!B:P,15,0) -> 112.8872 | AP16: =AO16*AN16 -> 17.72329 | AS16: =AS15 -> 143
A17: 4 | B17: =B16 -> 3 | C17: =C16 -> ET-COVER | D17: =MID(E17,9,2) -> PT | E17: =E16 -> RTHTMTBNPT72X45X10 | F17: =F16 -> RTHTMTBNPT | G17: =G16 -> 72X45X10 | H17: =H16 -> 72X45X10 | I17: =I16 -> 3 | J17: =J16 -> 6 | K17: =K16 -> 72 | L17: =L16 -> 45 | M17: =M16 -> 10 | N17: ="SFG-FRBNPK-ET-CVR-"&K17&"X"&L17&"X"&M17 -> SFG-FRBNPK-ET-CVR-72X45X10 | P17: =ROUND(((((K17+L17+K17+L17)+3))*0.0254),3) -> 6.02 | Q17: =P17=AJ17 -> TRUE | S17: ="Restonic Hotel Motel ET Cover "&K17&"X"&L17&"X"&M17 -> Restonic Hotel Motel ET Cover 72X45X10 | T17: =T16 -> SFG-FRBNPK-ET-CVR-72X45X10 | U17: =T17=N17 -> TRUE | V17: =S17=W17 -> TRUE | W17: =W16 -> Restonic Hotel Motel ET Cover 72X45X10 | X17: Standard | Y17: Production | Z17: TAIL-ET-PT | AA17: NOS | AB17: 1 | AC17: MRP&Rollup | AD17: CBESFG | AE17: 40 | AF17: I | AG17: SFG-RTHTMT-BNPK-ETBOR-11CM | AH17: Hotel Motel Poc ET-10 & 12 8MM/16D Pre Foam Border 11 CM Height | AI17: MTR | AJ17: =P17 -> 6.02 | AK17: CBESFG | AL17: Backflush | AM17: Active | AN17: =AJ17 -> 6.02 | AO17: =VLOOKUP(AG17,'SFG-rate rm - feb-24'!A:B,2,0) -> 19.60538 | AP17: =AO17*AN17 -> 118.02439 | AS17: =AS16 -> 143
A18: 5 | B18: =B17 -> 3 | C18: =C17 -> ET-COVER | D18: =MID(E18,9,2) -> PT | E18: =E17 -> RTHTMTBNPT72X45X10 | F18: =F17 -> RTHTMTBNPT | G18: =G17 -> 72X45X10 | H18: =H17 -> 72X45X10 | I18: =I17 -> 3 | J18: =J17 -> 6 | K18: =K17 -> 72 | L18: =L17 -> 45 | M18: =M17 -> 10 | N18: ="SFG-FRBNPK-ET-CVR-"&K18&"X"&L18&"X"&M18 -> SFG-FRBNPK-ET-CVR-72X45X10 | P18: 10 | Q18: =P18=AJ18 -> TRUE | S18: ="Restonic Hotel Motel ET Cover "&K18&"X"&L18&"X"&M18 -> Restonic Hotel Motel ET Cover 72X45X10 | T18: =T17 -> SFG-FRBNPK-ET-CVR-72X45X10 | U18: =T18=N18 -> TRUE | V18: =S18=W18 -> TRUE | W18: =W17 -> Restonic Hotel Motel ET Cover 72X45X10 | X18: Standard | Y18: Production | Z18: TAIL-ET-PT | AA18: NOS | AB18: 1 | AC18: MRP&Rollup | AD18: CBESFG | AE18: 50 | AF18: I | AG18: HW-CTON-THREAD | AH18: COTTON THREAD WHITE 3PLY | AI18: MTR | AJ18: =P18 -> 10 | AK18: CBEWIP | AL18: Backflush | AM18: Active | AN18: =AJ18/5000 -> 0.002 | AO18: =VLOOKUP(AG18,'RM-cost - feb-24'!B:P,15,0) -> 58 | AP18: =AO18*AN18 -> 0.116 | AS18: =AS17 -> 143
A20: 1 | B20: 4 | C20: ET-COVER | D20: =MID(E20,9,2) -> PT | E20: RTHTMTBNPT72X51X10 | F20: =LEFT(E20,MIN(FIND({0,1,2,3,4,5,6,7,8,9},E20&"0123456789"))-1) -> RTHTMTBNPT | G20: =SUBSTITUTE(E20,F20,"") -> 72X51X10 | H20: =IFERROR(LEFT(G20,FIND("-",G20)-1),G20) -> 72X51X10 | I20: =SEARCH("X",H20) -> 3 | J20: =SEARCH("X",H20,I20+1) -> 6 | K20: =LEFT(G20,SEARCH("x",G20)-1) -> 72 | L20: =MID(H20,I20+1,J20-I20-1) -> 51 | M20: =MID(H20,J20+1,20) -> 10 | N20: ="SFG-FRBNPK-ET-CVR-"&K20&"X"&L20&"X"&M20 -> SFG-FRBNPK-ET-CVR-72X51X10 | P20: =ROUND(((((K20+L20+K20+L20)+3)*0.0254)*5.3196),3) -> 33.644 | Q20: 0 | R20: =P20+Q20 -> 33.644 | S20: ="Restonic Hotel Motel ET Cover "&K20&"X"&L20&"X"&M20 -> Restonic Hotel Motel ET Cover 72X51X10 | T20: =N20 -> SFG-FRBNPK-ET-CVR-72X51X10 | U20: =T20=N20 -> TRUE | V20: =S20=W20 -> TRUE | W20: =S20 -> Restonic Hotel Motel ET Cover 72X51X10 | X20: Standard | Y20: Production | Z20: TAIL-ET-PT | AA20: NOS | AB20: 1 | AC20: MRP&Rollup | AD20: CBESFG | AE20: 10 | AF20: I | AG20: RM-THRD-QS-TKT40 | AH20: THREAD TKT40 210D/3 PLY 10000MTS | AI20: MTR | AJ20: =R20 -> 33.644 | AK20: CBEWIP | AL20: Backflush | AM20: Active | AN20: =AJ20/10000 -> 0.0033644 | AO20: =VLOOKUP(AG20,'RM-cost - feb-24'!B:P,15,0) -> 231.1423 | AP20: =AO20*AN20 -> 0.77765515 | AQ20: =SUM(AP20:AP24) -> 151.36812 | AR20: =ROUND(AQ20,0) -> 151 | AS20: =AR20 -> 151 | AT20: =+AS20+AY20 -> 169.6861 | AU20: =+SUM(((AS20*3%*18%))) -> 0.8154 | AV20: =+SUM(((AS20*14.33%*53%))) -> 11.468299 | AW20: =+SUM(((AS20*5.92%*53%))) -> 4.737776 | AX20: =+SUM(((AS20*2.08%*53%))) -> 1.664624 | AY20: =SUM(AU20:AX24) -> 18.686099 | AZ20: =ROUNDUP(AT20,0) -> 170 | BA20: =AZ20 -> 170
A21: 2 | B21: =B20 -> 4 | C21: =C20 -> ET-COVER | D21: =MID(E21,9,2) -> PT | E21: =E20 -> RTHTMTBNPT72X51X10 | F21: =F20 -> RTHTMTBNPT | G21: =G20 -> 72X51X10 | H21: =H20 -> 72X51X10 | I21: =I20 -> 3 | J21: =J20 -> 6 | K21: =K20 -> 72 | L21: =L20 -> 51 | M21: =M20 -> 10 | N21: ="SFG-FRBNPK-ET-CVR-"&K21&"X"&L21&"X"&M21 -> SFG-FRBNPK-ET-CVR-72X51X10 | O21: =K21*L21/144 -> 25.5 | P21: =ROUNDUP((((K21*L21/144)*0.003)),3) -> 0.077 | S21: ="Restonic Hotel Motel ET Cover "&K21&"X"&L21&"X"&M21 -> Restonic Hotel Motel ET Cover 72X51X10 | T21: =T20 -> SFG-FRBNPK-ET-CVR-72X51X10 | U21: =T21=N21 -> TRUE | V21: =S21=W21 -> TRUE | W21: =W20 -> Restonic Hotel Motel ET Cover 72X51X10 | X21: Standard | Y21: Production | Z21: TAIL-ET-PT | AA21: NOS | AB21: 1 | AC21: MRP&Rollup | AD21: CBESFG | AE21: 20 | AF21: I | AG21: RM-NWN-70GSMX6INCH | AH21: NON WOVEN FABRIC 70GSMX6" | AI21: KGS | AJ21: 0.061 | AK21: CBEWIP | AL21: Backflush | AM21: Active | AN21: =AJ21 -> 0.061 | AO21: =VLOOKUP(AG21,'RM-cost - feb-24'!B:P,15,0) -> 113.786 | AP21: =AO21*AN21 -> 6.940946 | AS21: =AS20 -> 151
A22: 3 | B22: =B21 -> 4 | C22: =C21 -> ET-COVER | D22: =MID(E22,9,2) -> PT | E22: =E21 -> RTHTMTBNPT72X51X10 | F22: =F21 -> RTHTMTBNPT | G22: =G21 -> 72X51X10 | H22: =H21 -> 72X51X10 | I22: =I21 -> 3 | J22: =J21 -> 6 | K22: =K21 -> 72 | L22: =L21 -> 51 | M22: =M21 -> 10 | N22: ="SFG-FRBNPK-ET-CVR-"&K22&"X"&L22&"X"&M22 -> SFG-FRBNPK-ET-CVR-72X51X10 | P22: =ROUNDUP((((K22*L22/144)*0.00692)),3) -> 0.177 | Q22: =P22=AJ22 -> FALSE | S22: ="Restonic Hotel Motel ET Cover "&K22&"X"&L22&"X"&M22 -> Restonic Hotel Motel ET Cover 72X51X10 | T22: =T21 -> SFG-FRBNPK-ET-CVR-72X51X10 | U22: =T22=N22 -> TRUE | V22: =S22=W22 -> TRUE | W22: =W21 -> Restonic Hotel Motel ET Cover 72X51X10 | X22: Standard | Y22: Production | Z22: TAIL-ET-PT | AA22: NOS | AB22: 1 | AC22: MRP&Rollup | AD22: CBESFG | AE22: 30 | AF22: I | AG22: RML-NWN-70GSMX76" | AH22: NON WOVEN FABRIC WHITE 70 GSM 76 INCH | AI22: KGS | AJ22: 0.173 | AK22: CBEWIP | AL22: Backflush | AM22: Active | AN22: =AJ22 -> 0.173 | AO22: =VLOOKUP(AG22,'RM-cost - feb-24'!B:P,15,0) -> 112.8872 | AP22: =AO22*AN22 -> 19.529486 | AS22: =AS21 -> 151
A23: 4 | B23: =B22 -> 4 | C23: =C22 -> ET-COVER | D23: =MID(E23,9,2) -> PT | E23: =E22 -> RTHTMTBNPT72X51X10 | F23: =F22 -> RTHTMTBNPT | G23: =G22 -> 72X51X10 | H23: =H22 -> 72X51X10 | I23: =I22 -> 3 | J23: =J22 -> 6 | K23: =K22 -> 72 | L23: =L22 -> 51 | M23: =M22 -> 10 | N23: ="SFG-FRBNPK-ET-CVR-"&K23&"X"&L23&"X"&M23 -> SFG-FRBNPK-ET-CVR-72X51X10 | P23: =ROUND(((((K23+L23+K23+L23)+3))*0.0254),3) -> 6.325 | Q23: =P23=AJ23 -> TRUE | S23: ="Restonic Hotel Motel ET Cover "&K23&"X"&L23&"X"&M23 -> Restonic Hotel Motel ET Cover 72X51X10 | T23: =T22 -> SFG-FRBNPK-ET-CVR-72X51X10 | U23: =T23=N23 -> TRUE | V23: =S23=W23 -> TRUE | W23: =W22 -> Restonic Hotel Motel ET Cover 72X51X10 | X23: Standard | Y23: Production | Z23: TAIL-ET-PT | AA23: NOS | AB23: 1 | AC23: MRP&Rollup | AD23: CBESFG | AE23: 40 | AF23: I | AG23: SFG-RTHTMT-BNPK-ETBOR-11CM | AH23: Hotel Motel Poc ET-10 & 12 8MM/16D Pre Foam Border 11 CM Height | AI23: MTR | AJ23: =P23 -> 6.325 | AK23: CBESFG | AL23: Backflush | AM23: Active | AN23: =AJ23 -> 6.325 | AO23: =VLOOKUP(AG23,'SFG-rate rm - feb-24'!A:B,2,0) -> 19.60538 | AP23: =AO23*AN23 -> 124.00403 | AS23: =AS22 -> 151
A24: 5 | B24: =B23 -> 4 | C24: =C23 -> ET-COVER | D24: =MID(E24,9,2) -> PT | E24: =E23 -> RTHTMTBNPT72X51X10 | F24: =F23 -> RTHTMTBNPT | G24: =G23 -> 72X51X10 | H24: =H23 -> 72X51X10 | I24: =I23 -> 3 | J24: =J23 -> 6 | K24: =K23 -> 72 | L24: =L23 -> 51 | M24: =M23 -> 10 | N24: ="SFG-FRBNPK-ET-CVR-"&K24&"X"&L24&"X"&M24 -> SFG-FRBNPK-ET-CVR-72X51X10 | P24: 10 | Q24: =P24=AJ24 -> TRUE | S24: ="Restonic Hotel Motel ET Cover "&K24&"X"&L24&"X"&M24 -> Restonic Hotel Motel ET Cover 72X51X10 | T24: =T23 -> SFG-FRBNPK-ET-CVR-72X51X10 | U24: =T24=N24 -> TRUE | V24: =S24=W24 -> TRUE | W24: =W23 -> Restonic Hotel Motel ET Cover 72X51X10 | X24: Standard | Y24: Production | Z24: TAIL-ET-PT | AA24: NOS | AB24: 1 | AC24: MRP&Rollup | AD24: CBESFG | AE24: 50 | AF24: I | AG24: HW-CTON-THREAD | AH24: COTTON THREAD WHITE 3PLY | AI24: MTR | AJ24: =P24 -> 10 | AK24: CBEWIP | AL24: Backflush | AM24: Active | AN24: =AJ24/5000 -> 0.002 | AO24: =VLOOKUP(AG24,'RM-cost - feb-24'!B:P,15,0) -> 58 | AP24: =AO24*AN24 -> 0.116 | AS24: =AS23 -> 151
A26: 1 | B26: 5 | C26: ET-COVER | D26: =MID(E26,9,2) -> PT | E26: RTHTMTBNPT72X54X10 | F26: =LEFT(E26,MIN(FIND({0,1,2,3,4,5,6,7,8,9},E26&"0123456789"))-1) -> RTHTMTBNPT | G26: =SUBSTITUTE(E26,F26,"") -> 72X54X10 | H26: =IFERROR(LEFT(G26,FIND("-",G26)-1),G26) -> 72X54X10 | I26: =SEARCH("X",H26) -> 3 | J26: =SEARCH("X",H26,I26+1) -> 6 | K26: =LEFT(G26,SEARCH("x",G26)-1) -> 72 | L26: =MID(H26,I26+1,J26-I26-1) -> 54 | M26: =MID(H26,J26+1,20) -> 10 | N26: ="SFG-FRBNPK-ET-CVR-"&K26&"X"&L26&"X"&M26 -> SFG-FRBNPK-ET-CVR-72X54X10 | P26: =ROUND(((((K26+L26+K26+L26)+3)*0.0254)*5.3196),3) -> 34.455 | Q26: 0 | R26: =P26+Q26 -> 34.455 | S26: ="Restonic Hotel Motel ET Cover "&K26&"X"&L26&"X"&M26 -> Restonic Hotel Motel ET Cover 72X54X10 | T26: =N26 -> SFG-FRBNPK-ET-CVR-72X54X10 | U26: =T26=N26 -> TRUE | V26: =S26=W26 -> TRUE | W26: =S26 -> Restonic Hotel Motel ET Cover 72X54X10 | X26: Standard | Y26: Production | Z26: TAIL-ET-PT | AA26: NOS | AB26: 1 | AC26: MRP&Rollup | AD26: CBESFG | AE26: 10 | AF26: I | AG26: RM-THRD-QS-TKT40 | AH26: THREAD TKT40 210D/3 PLY 10000MTS | AI26: MTR | AJ26: =R26 -> 34.455 | AK26: CBEWIP | AL26: Backflush | AM26: Active | AN26: =AJ26/10000 -> 0.0034455 | AO26: =VLOOKUP(AG26,'RM-cost - feb-24'!B:P,15,0) -> 231.1423 | AP26: =AO26*AN26 -> 0.79640079 | AQ26: =SUM(AP26:AP30) -> 155.9491 | AR26: =ROUND(AQ26,0) -> 156 | AS26: =AR26 -> 156 | AT26: =+AS26+AY26 -> 175.30484 | AU26: =+SUM(((AS26*3%*18%))) -> 0.8424 | AV26: =+SUM(((AS26*14.33%*53%))) -> 11.848044 | AW26: =+SUM(((AS26*5.92%*53%))) -> 4.894656 | AX26: =+SUM(((AS26*2.08%*53%))) -> 1.719744 | AY26: =SUM(AU26:AX30) -> 19.304844 | AZ26: =ROUNDUP(AT26,0) -> 176 | BA26: =AZ26 -> 176
A27: 2 | B27: =B26 -> 5 | C27: =C26 -> ET-COVER | D27: =MID(E27,9,2) -> PT | E27: =E26 -> RTHTMTBNPT72X54X10 | F27: =F26 -> RTHTMTBNPT | G27: =G26 -> 72X54X10 | H27: =H26 -> 72X54X10 | I27: =I26 -> 3 | J27: =J26 -> 6 | K27: =K26 -> 72 | L27: =L26 -> 54 | M27: =M26 -> 10 | N27: ="SFG-FRBNPK-ET-CVR-"&K27&"X"&L27&"X"&M27 -> SFG-FRBNPK-ET-CVR-72X54X10 | O27: =K27*L27/144 -> 27 | P27: =ROUNDUP((((K27*L27/144)*0.003)),3) -> 0.081 | S27: ="Restonic Hotel Motel ET Cover "&K27&"X"&L27&"X"&M27 -> Restonic Hotel Motel ET Cover 72X54X10 | T27: =T26 -> SFG-FRBNPK-ET-CVR-72X54X10 | U27: =T27=N27 -> TRUE | V27: =S27=W27 -> TRUE | W27: =W26 -> Restonic Hotel Motel ET Cover 72X54X10 | X27: Standard | Y27: Production | Z27: TAIL-ET-PT | AA27: NOS | AB27: 1 | AC27: MRP&Rollup | AD27: CBESFG | AE27: 20 | AF27: I | AG27: RM-NWN-70GSMX6INCH | AH27: NON WOVEN FABRIC 70GSMX6" | AI27: KGS | AJ27: 0.063 | AK27: CBEWIP | AL27: Backflush | AM27: Active | AN27: =AJ27 -> 0.063 | AO27: =VLOOKUP(AG27,'RM-cost - feb-24'!B:P,15,0) -> 113.786 | AP27: =AO27*AN27 -> 7.168518 | AS27: =AS26 -> 156
A28: 3 | B28: =B27 -> 5 | C28: =C27 -> ET-COVER | D28: =MID(E28,9,2) -> PT | E28: =E27 -> RTHTMTBNPT72X54X10 | F28: =F27 -> RTHTMTBNPT | G28: =G27 -> 72X54X10 | H28: =H27 -> 72X54X10 | I28: =I27 -> 3 | J28: =J27 -> 6 | K28: =K27 -> 72 | L28: =L27 -> 54 | M28: =M27 -> 10 | N28: ="SFG-FRBNPK-ET-CVR-"&K28&"X"&L28&"X"&M28 -> SFG-FRBNPK-ET-CVR-72X54X10 | P28: =ROUNDUP((((K28*L28/144)*0.00692)),3) -> 0.187 | Q28: =P28=AJ28 -> FALSE | S28: ="Restonic Hotel Motel ET Cover "&K28&"X"&L28&"X"&M28 -> Restonic Hotel Motel ET Cover 72X54X10 | T28: =T27 -> SFG-FRBNPK-ET-CVR-72X54X10 | U28: =T28=N28 -> TRUE | V28: =S28=W28 -> TRUE | W28: =W27 -> Restonic Hotel Motel ET Cover 72X54X10 | X28: Standard | Y28: Production | Z28: TAIL-ET-PT | AA28: NOS | AB28: 1 | AC28: MRP&Rollup | AD28: CBESFG | AE28: 30 | AF28: I | AG28: RML-NWN-70GSMX76" | AH28: NON WOVEN FABRIC WHITE 70 GSM 76 INCH | AI28: KGS | AJ28: 0.185 | AK28: CBEWIP | AL28: Backflush | AM28: Active | AN28: =AJ28 -> 0.185 | AO28: =VLOOKUP(AG28,'RM-cost - feb-24'!B:P,15,0) -> 112.8872 | AP28: =AO28*AN28 -> 20.884132 | AS28: =AS27 -> 156
A29: 4 | B29: =B28 -> 5 | C29: =C28 -> ET-COVER | D29: =MID(E29,9,2) -> PT | E29: =E28 -> RTHTMTBNPT72X54X10 | F29: =F28 -> RTHTMTBNPT | G29: =G28 -> 72X54X10 | H29: =H28 -> 72X54X10 | I29: =I28 -> 3 | J29: =J28 -> 6 | K29: =K28 -> 72 | L29: =L28 -> 54 | M29: =M28 -> 10 | N29: ="SFG-FRBNPK-ET-CVR-"&K29&"X"&L29&"X"&M29 -> SFG-FRBNPK-ET-CVR-72X54X10 | P29: =ROUND(((((K29+L29+K29+L29)+3))*0.0254),3) -> 6.477 | Q29: =P29=AJ29 -> TRUE | S29: ="Restonic Hotel Motel ET Cover "&K29&"X"&L29&"X"&M29 -> Restonic Hotel Motel ET Cover 72X54X10 | T29: =T28 -> SFG-FRBNPK-ET-CVR-72X54X10 | U29: =T29=N29 -> TRUE | V29: =S29=W29 -> TRUE | W29: =W28 -> Restonic Hotel Motel ET Cover 72X54X10 | X29: Standard | Y29: Production | Z29: TAIL-ET-PT | AA29: NOS | AB29: 1 | AC29: MRP&Rollup | AD29: CBESFG | AE29: 40 | AF29: I | AG29: SFG-RTHTMT-BNPK-ETBOR-11CM | AH29: Hotel Motel Poc ET-10 & 12 8MM/16D Pre Foam Border 11 CM Height | AI29: MTR | AJ29: =P29 -> 6.477 | AK29: CBESFG | AL29: Backflush | AM29: Active | AN29: =AJ29 -> 6.477 | AO29: =VLOOKUP(AG29,'SFG-rate rm - feb-24'!A:B,2,0) -> 19.60538 | AP29: =AO29*AN29 -> 126.98405 | AS29: =AS28 -> 156
A30: 5 | B30: =B29 -> 5 | C30: =C29 -> ET-COVER | D30: =MID(E30,9,2) -> PT | E30: =E29 -> RTHTMTBNPT72X54X10 | F30: =F29 -> RTHTMTBNPT | G30: =G29 -> 72X54X10 | H30: =H29 -> 72X54X10 | I30: =I29 -> 3 | J30: =J29 -> 6 | K30: =K29 -> 72 | L30: =L29 -> 54 | M30: =M29 -> 10 | N30: ="SFG-FRBNPK-ET-CVR-"&K30&"X"&L30&"X"&M30 -> SFG-FRBNPK-ET-CVR-72X54X10 | P30: 10 | Q30: =P30=AJ30 -> TRUE | S30: ="Restonic Hotel Motel ET Cover "&K30&"X"&L30&"X"&M30 -> Restonic Hotel Motel ET Cover 72X54X10 | T30: =T29 -> SFG-FRBNPK-ET-CVR-72X54X10 | U30: =T30=N30 -> TRUE | V30: =S30=W30 -> TRUE | W30: =W29 -> Restonic Hotel Motel ET Cover 72X54X10 | X30: Standard | Y30: Production | Z30: TAIL-ET-PT | AA30: NOS | AB30: 1 | AC30: MRP&Rollup | AD30: CBESFG | AE30: 50 | AF30: I | AG30: HW-CTON-THREAD | AH30: COTTON THREAD WHITE 3PLY | AI30: MTR | AJ30: =P30 -> 10 | AK30: CBEWIP | AL30: Backflush | AM30: Active | AN30: =AJ30/5000 -> 0.002 | AO30: =VLOOKUP(AG30,'RM-cost - feb-24'!B:P,15,0) -> 58 | AP30: =AO30*AN30 -> 0.116 | AS30: =AS29 -> 156
A32: 1 | B32: 6 | C32: ET-COVER | D32: =MID(E32,9,2) -> PT | E32: RTHTMTBNPT72X57X10 | F32: =LEFT(E32,MIN(FIND({0,1,2,3,4,5,6,7,8,9},E32&"0123456789"))-1) -> RTHTMTBNPT | G32: =SUBSTITUTE(E32,F32,"") -> 72X57X10 | H32: =IFERROR(LEFT(G32,FIND("-",G32)-1),G32) -> 72X57X10 | I32: =SEARCH("X",H32) -> 3 | J32: =SEARCH("X",H32,I32+1) -> 6 | K32: =LEFT(G32,SEARCH("x",G32)-1) -> 72 | L32: =MID(H32,I32+1,J32-I32-1) -> 57 | M32: =MID(H32,J32+1,20) -> 10 | N32: ="SFG-FRBNPK-ET-CVR-"&K32&"X"&L32&"X"&M32 -> SFG-FRBNPK-ET-CVR-72X57X10 | P32: =ROUND(((((K32+L32+K32+L32)+3)*0.0254)*5.3196),3) -> 35.266 | Q32: 0 | R32: =P32+Q32 -> 35.266 | S32: ="Restonic Hotel Motel ET Cover "&K32&"X"&L32&"X"&M32 -> Restonic Hotel Motel ET Cover 72X57X10 | T32: =N32 -> SFG-FRBNPK-ET-CVR-72X57X10 | U32: =T32=N32 -> TRUE | V32: =S32=W32 -> TRUE | W32: =S32 -> Restonic Hotel Motel ET Cover 72X57X10 | X32: Standard | Y32: Production | Z32: TAIL-ET-PT | AA32: NOS | AB32: 1 | AC32: MRP&Rollup | AD32: CBESFG | AE32: 10 | AF32: I | AG32: RM-THRD-QS-TKT40 | AH32: THREAD TKT40 210D/3 PLY 10000MTS | AI32: MTR | AJ32: =R32 -> 35.266 | AK32: CBEWIP | AL32: Backflush | AM32: Active | AN32: =AJ32/10000 -> 0.0035266 | AO32: =VLOOKUP(AG32,'RM-cost - feb-24'!B:P,15,0) -> 231.1423 | AP32: =AO32*AN32 -> 0.81514644 | AQ32: =SUM(AP32:AP36) -> 160.41719 | AR32: =ROUND(AQ32,0) -> 160 | AS32: =AR32 -> 160 | AT32: =+AS32+AY32 -> 179.79984 | AU32: =+SUM(((AS32*3%*18%))) -> 0.864 | AV32: =+SUM(((AS32*14.33%*53%))) -> 12.15184 | AW32: =+SUM(((AS32*5.92%*53%))) -> 5.02016 | AX32: =+SUM(((AS32*2.08%*53%))) -> 1.76384 | AY32: =SUM(AU32:AX36) -> 19.79984 | AZ32: =ROUNDUP(AT32,0) -> 180 | BA32: =AZ32 -> 180
A33: 2 | B33: =B32 -> 6 | C33: =C32 -> ET-COVER | D33: =MID(E33,9,2) -> PT | E33: =E32 -> RTHTMTBNPT72X57X10 | F33: =F32 -> RTHTMTBNPT | G33: =G32 -> 72X57X10 | H33: =H32 -> 72X57X10 | I33: =I32 -> 3 | J33: =J32 -> 6 | K33: =K32 -> 72 | L33: =L32 -> 57 | M33: =M32 -> 10 | N33: ="SFG-FRBNPK-ET-CVR-"&K33&"X"&L33&"X"&M33 -> SFG-FRBNPK-ET-CVR-72X57X10 | O33: =K33*L33/144 -> 28.5 | P33: =ROUNDUP((((K33*L33/144)*0.003)),3) -> 0.086 | S33: ="Restonic Hotel Motel ET Cover "&K33&"X"&L33&"X"&M33 -> Restonic Hotel Motel ET Cover 72X57X10 | T33: =T32 -> SFG-FRBNPK-ET-CVR-72X57X10 | U33: =T33=N33 -> TRUE | V33: =S33=W33 -> TRUE | W33: =W32 -> Restonic Hotel Motel ET Cover 72X57X10 | X33: Standard | Y33: Production | Z33: TAIL-ET-PT | AA33: NOS | AB33: 1 | AC33: MRP&Rollup | AD33: CBESFG | AE33: 20 | AF33: I | AG33: RM-NWN-70GSMX6INCH | AH33: NON WOVEN FABRIC 70GSMX6" | AI33: KGS | AJ33: 0.065 | AK33: CBEWIP | AL33: Backflush | AM33: Active | AN33: =AJ33 -> 0.065 | AO33: =VLOOKUP(AG33,'RM-cost - feb-24'!B:P,15,0) -> 113.786 | AP33: =AO33*AN33 -> 7.39609 | AS33: =AS32 -> 160
A34: 3 | B34: =B33 -> 6 | C34: =C33 -> ET-COVER | D34: =MID(E34,9,2) -> PT | E34: =E33 -> RTHTMTBNPT72X57X10 | F34: =F33 -> RTHTMTBNPT | G34: =G33 -> 72X57X10 | H34: =H33 -> 72X57X10 | I34: =I33 -> 3 | J34: =J33 -> 6 | K34: =K33 -> 72 | L34: =L33 -> 57 | M34: =M33 -> 10 | N34: ="SFG-FRBNPK-ET-CVR-"&K34&"X"&L34&"X"&M34 -> SFG-FRBNPK-ET-CVR-72X57X10 | P34: =ROUNDUP((((K34*L34/144)*0.00692)),3) -> 0.198 | Q34: =P34=AJ34 -> FALSE | S34: ="Restonic Hotel Motel ET Cover "&K34&"X"&L34&"X"&M34 -> Restonic Hotel Motel ET Cover 72X57X10 | T34: =T33 -> SFG-FRBNPK-ET-CVR-72X57X10 | U34: =T34=N34 -> TRUE | V34: =S34=W34 -> TRUE | W34: =W33 -> Restonic Hotel Motel ET Cover 72X57X10 | X34: Standard | Y34: Production | Z34: TAIL-ET-PT | AA34: NOS | AB34: 1 | AC34: MRP&Rollup | AD34: CBESFG | AE34: 30 | AF34: I | AG34: RML-NWN-70GSMX76" | AH34: NON WOVEN FABRIC WHITE 70 GSM 76 INCH | AI34: KGS | AJ34: 0.196 | AK34: CBEWIP | AL34: Backflush | AM34: Active | AN34: =AJ34 -> 0.196 | AO34: =VLOOKUP(AG34,'RM-cost - feb-24'!B:P,15,0) -> 112.8872 | AP34: =AO34*AN34 -> 22.125891 | AS34: =AS33 -> 160
A35: 4 | B35: =B34 -> 6 | C35: =C34 -> ET-COVER | D35: =MID(E35,9,2) -> PT | E35: =E34 -> RTHTMTBNPT72X57X10 | F35: =F34 -> RTHTMTBNPT | G35: =G34 -> 72X57X10 | H35: =H34 -> 72X57X10 | I35: =I34 -> 3 | J35: =J34 -> 6 | K35: =K34 -> 72 | L35: =L34 -> 57 | M35: =M34 -> 10 | N35: ="SFG-FRBNPK-ET-CVR-"&K35&"X"&L35&"X"&M35 -> SFG-FRBNPK-ET-CVR-72X57X10 | P35: =ROUND(((((K35+L35+K35+L35)+3))*0.0254),3) -> 6.629 | Q35: =P35=AJ35 -> TRUE | S35: ="Restonic Hotel Motel ET Cover "&K35&"X"&L35&"X"&M35 -> Restonic Hotel Motel ET Cover 72X57X10 | T35: =T34 -> SFG-FRBNPK-ET-CVR-72X57X10 | U35: =T35=N35 -> TRUE | V35: =S35=W35 -> TRUE | W35: =W34 -> Restonic Hotel Motel ET Cover 72X57X10 | X35: Standard | Y35: Production | Z35: TAIL-ET-PT | AA35: NOS | AB35: 1 | AC35: MRP&Rollup | AD35: CBESFG | AE35: 40 | AF35: I | AG35: SFG-RTHTMT-BNPK-ETBOR-11CM | AH35: Hotel Motel Poc ET-10 & 12 8MM/16D Pre Foam Border 11 CM Height | AI35: MTR | AJ35: =P35 -> 6.629 | AK35: CBESFG | AL35: Backflush | AM35: Active | AN35: =AJ35 -> 6.629 | AO35: =VLOOKUP(AG35,'SFG-rate rm - feb-24'!A:B,2,0) -> 19.60538 | AP35: =AO35*AN35 -> 129.96407 | AS35: =AS34 -> 160
A36: 5 | B36: =B35 -> 6 | C36: =C35 -> ET-COVER | D36: =MID(E36,9,2) -> PT | E36: =E35 -> RTHTMTBNPT72X57X10 | F36: =F35 -> RTHTMTBNPT | G36: =G35 -> 72X57X10 | H36: =H35 -> 72X57X10 | I36: =I35 -> 3 | J36: =J35 -> 6 | K36: =K35 -> 72 | L36: =L35 -> 57 | M36: =M35 -> 10 | N36: ="SFG-FRBNPK-ET-CVR-"&K36&"X"&L36&"X"&M36 -> SFG-FRBNPK-ET-CVR-72X57X10 | P36: 10 | Q36: =P36=AJ36 -> TRUE | S36: ="Restonic Hotel Motel ET Cover "&K36&"X"&L36&"X"&M36 -> Restonic Hotel Motel ET Cover 72X57X10 | T36: =T35 -> SFG-FRBNPK-ET-CVR-72X57X10 | U36: =T36=N36 -> TRUE | V36: =S36=W36 -> TRUE | W36: =W35 -> Restonic Hotel Motel ET Cover 72X57X10 | X36: Standard | Y36: Production | Z36: TAIL-ET-PT | AA36: NOS | AB36: 1 | AC36: MRP&Rollup | AD36: CBESFG | AE36: 50 | AF36: I | AG36: HW-CTON-THREAD | AH36: COTTON THREAD WHITE 3PLY | AI36: MTR | AJ36: =P36 -> 10 | AK36: CBEWIP | AL36: Backflush | AM36: Active | AN36: =AJ36/5000 -> 0.002 | AO36: =VLOOKUP(AG36,'RM-cost - feb-24'!B:P,15,0) -> 58 | AP36: =AO36*AN36 -> 0.116 | AS36: =AS35 -> 160
A38: 1 | B38: 7 | C38: ET-COVER | D38: =MID(E38,9,2) -> PT | E38: RTHTMTBNPT72X63X10 | F38: =LEFT(E38,MIN(FIND({0,1,2,3,4,5,6,7,8,9},E38&"0123456789"))-1) -> RTHTMTBNPT | G38: =SUBSTITUTE(E38,F38,"") -> 72X63X10 | H38: =IFERROR(LEFT(G38,FIND("-",G38)-1),G38) -> 72X63X10 | I38: =SEARCH("X",H38) -> 3 | J38: =SEARCH("X",H38,I38+1) -> 6 | K38: =LEFT(G38,SEARCH("x",G38)-1) -> 72 | L38: =MID(H38,I38+1,J38-I38-1) -> 63 | M38: =MID(H38,J38+1,20) -> 10 | N38: ="SFG-FRBNPK-ET-CVR-"&K38&"X"&L38&"X"&M38 -> SFG-FRBNPK-ET-CVR-72X63X10 | P38: =ROUND(((((K38+L38+K38+L38)+3)*0.0254)*5.3196),3) -> 36.887 | Q38: 0 | R38: =P38+Q38 -> 36.887 | S38: ="Restonic Hotel Motel ET Cover "&K38&"X"&L38&"X"&M38 -> Restonic Hotel Motel ET Cover 72X63X10 | T38: =N38 -> SFG-FRBNPK-ET-CVR-72X63X10 | U38: =T38=N38 -> TRUE | V38: =S38=W38 -> TRUE | W38: =S38 -> Restonic Hotel Motel ET Cover 72X63X10 | X38: Standard | Y38: Production | Z38: TAIL-ET-PT | AA38: NOS | AB38: 1 | AC38: MRP&Rollup | AD38: CBESFG | AE38: 10 | AF38: I | AG38: RM-THRD-QS-TKT40 | AH38: THREAD TKT40 210D/3 PLY 10000MTS | AI38: MTR | AJ38: =R38 -> 36.887 | AK38: CBEWIP | AL38: Backflush | AM38: Active | AN38: =AJ38/10000 -> 0.0036887 | AO38: =VLOOKUP(AG38,'RM-cost - feb-24'!B:P,15,0) -> 231.1423 | AP38: =AO38*AN38 -> 0.8526146 | AQ38: =SUM(AP38:AP42) -> 169.37207 | AR38: =ROUND(AQ38,0) -> 169 | AS38: =AR38 -> 169 | AT38: =+AS38+AY38 -> 189.91358 | AU38: =+SUM(((AS38*3%*18%))) -> 0.9126 | AV38: =+SUM(((AS38*14.33%*53%))) -> 12.835381 | AW38: =+SUM(((AS38*5.92%*53%))) -> 5.302544 | AX38: =+SUM(((AS38*2.08%*53%))) -> 1.863056 | AY38: =SUM(AU38:AX42) -> 20.913581 | AZ38: =ROUNDUP(AT38,0) -> 190 | BA38: =AZ38 -> 190
A39: 2 | B39: =B38 -> 7 | C39: =C38 -> ET-COVER | D39: =MID(E39,9,2) -> PT | E39: =E38 -> RTHTMTBNPT72X63X10 | F39: =F38 -> RTHTMTBNPT | G39: =G38 -> 72X63X10 | H39: =H38 -> 72X63X10 | I39: =I38 -> 3 | J39: =J38 -> 6 | K39: =K38 -> 72 | L39: =L38 -> 63 | M39: =M38 -> 10 | N39: ="SFG-FRBNPK-ET-CVR-"&K39&"X"&L39&"X"&M39 -> SFG-FRBNPK-ET-CVR-72X63X10 | O39: =K39*L39/144 -> 31.5 | P39: =ROUNDUP((((K39*L39/144)*0.003)),3) -> 0.095 | S39: ="Restonic Hotel Motel ET Cover "&K39&"X"&L39&"X"&M39 -> Restonic Hotel Motel ET Cover 72X63X10 | T39: =T38 -> SFG-FRBNPK-ET-CVR-72X63X10 | U39: =T39=N39 -> TRUE | V39: =S39=W39 -> TRUE | W39: =W38 -> Restonic Hotel Motel ET Cover 72X63X10 | X39: Standard | Y39: Production | Z39: TAIL-ET-PT | AA39: NOS | AB39: 1 | AC39: MRP&Rollup | AD39: CBESFG | AE39: 20 | AF39: I | AG39: RM-NWN-70GSMX6INCH | AH39: NON WOVEN FABRIC 70GSMX6" | AI39: KGS | AJ39: 0.068 | AK39: CBEWIP | AL39: Backflush | AM39: Active | AN39: =AJ39 -> 0.068 | AO39: =VLOOKUP(AG39,'RM-cost - feb-24'!B:P,15,0) -> 113.786 | AP39: =AO39*AN39 -> 7.737448 | AS39: =AS38 -> 169
A40: 3 | B40: =B39 -> 7 | C40: =C39 -> ET-COVER | D40: =MID(E40,9,2) -> PT | E40: =E39 -> RTHTMTBNPT72X63X10 | F40: =F39 -> RTHTMTBNPT | G40: =G39 -> 72X63X10 | H40: =H39 -> 72X63X10 | I40: =I39 -> 3 | J40: =J39 -> 6 | K40: =K39 -> 72 | L40: =L39 -> 63 | M40: =M39 -> 10 | N40: ="SFG-FRBNPK-ET-CVR-"&K40&"X"&L40&"X"&M40 -> SFG-FRBNPK-ET-CVR-72X63X10 | P40: =ROUNDUP((((K40*L40/144)*0.00692)),3) -> 0.218 | Q40: =P40=AJ40 -> FALSE | S40: ="Restonic Hotel Motel ET Cover "&K40&"X"&L40&"X"&M40 -> Restonic Hotel Motel ET Cover 72X63X10 | T40: =T39 -> SFG-FRBNPK-ET-CVR-72X63X10 | U40: =T40=N40 -> TRUE | V40: =S40=W40 -> TRUE | W40: =W39 -> Restonic Hotel Motel ET Cover 72X63X10 | X40: Standard | Y40: Production | Z40: TAIL-ET-PT | AA40: NOS | AB40: 1 | AC40: MRP&Rollup | AD40: CBESFG | AE40: 30 | AF40: I | AG40: RML-NWN-70GSMX76" | AH40: NON WOVEN FABRIC WHITE 70 GSM 76 INCH | AI40: KGS | AJ40: 0.219 | AK40: CBEWIP | AL40: Backflush | AM40: Active | AN40: =AJ40 -> 0.219 | AO40: =VLOOKUP(AG40,'RM-cost - feb-24'!B:P,15,0) -> 112.8872 | AP40: =AO40*AN40 -> 24.722297 | AS40: =AS39 -> 169
A41: 4 | B41: =B40 -> 7 | C41: =C40 -> ET-COVER | D41: =MID(E41,9,2) -> PT | E41: =E40 -> RTHTMTBNPT72X63X10 | F41: =F40 -> RTHTMTBNPT | G41: =G40 -> 72X63X10 | H41: =H40 -> 72X63X10 | I41: =I40 -> 3 | J41: =J40 -> 6 | K41: =K40 -> 72 | L41: =L40 -> 63 | M41: =M40 -> 10 | N41: ="SFG-FRBNPK-ET-CVR-"&K41&"X"&L41&"X"&M41 -> SFG-FRBNPK-ET-CVR-72X63X10 | P41: =ROUND(((((K41+L41+K41+L41)+3))*0.0254),3) -> 6.934 | Q41: =P41=AJ41 -> TRUE | S41: ="Restonic Hotel Motel ET Cover "&K41&"X"&L41&"X"&M41 -> Restonic Hotel Motel ET Cover 72X63X10 | T41: =T40 -> SFG-FRBNPK-ET-CVR-72X63X10 | U41: =T41=N41 -> TRUE | V41: =S41=W41 -> TRUE | W41: =W40 -> Restonic Hotel Motel ET Cover 72X63X10 | X41: Standard | Y41: Production | Z41: TAIL-ET-PT | AA41: NOS | AB41: 1 | AC41: MRP&Rollup | AD41: CBESFG | AE41: 40 | AF41: I | AG41: SFG-RTHTMT-BNPK-ETBOR-11CM | AH41: Hotel Motel Poc ET-10 & 12 8MM/16D Pre Foam Border 11 CM Height | AI41: MTR | AJ41: =P41 -> 6.934 | AK41: CBESFG | AL41: Backflush | AM41: Active | AN41: =AJ41 -> 6.934 | AO41: =VLOOKUP(AG41,'SFG-rate rm - feb-24'!A:B,2,0) -> 19.60538 | AP41: =AO41*AN41 -> 135.94371 | AS41: =AS40 -> 169
A42: 5 | B42: =B41 -> 7 | C42: =C41 -> ET-COVER | D42: =MID(E42,9,2) -> PT | E42: =E41 -> RTHTMTBNPT72X63X10 | F42: =F41 -> RTHTMTBNPT | G42: =G41 -> 72X63X10 | H42: =H41 -> 72X63X10 | I42: =I41 -> 3 | J42: =J41 -> 6 | K42: =K41 -> 72 | L42: =L41 -> 63 | M42: =M41 -> 10 | N42: ="SFG-FRBNPK-ET-CVR-"&K42&"X"&L42&"X"&M42 -> SFG-FRBNPK-ET-CVR-72X63X10 | P42: 10 | Q42: =P42=AJ42 -> TRUE | S42: ="Restonic Hotel Motel ET Cover "&K42&"X"&L42&"X"&M42 -> Restonic Hotel Motel ET Cover 72X63X10 | T42: =T41 -> SFG-FRBNPK-ET-CVR-72X63X10 | U42: =T42=N42 -> TRUE | V42: =S42=W42 -> TRUE | W42: =W41 -> Restonic Hotel Motel ET Cover 72X63X10 | X42: Standard | Y42: Production | Z42: TAIL-ET-PT | AA42: NOS | AB42: 1 | AC42: MRP&Rollup | AD42: CBESFG | AE42: 50 | AF42: I | AG42: HW-CTON-THREAD | AH42: COTTON THREAD WHITE 3PLY | AI42: MTR | AJ42: =P42 -> 10 | AK42: CBEWIP | AL42: Backflush | AM42: Active | AN42: =AJ42/5000 -> 0.002 | AO42: =VLOOKUP(AG42,'RM-cost - feb-24'!B:P,15,0) -> 58 | AP42: =AO42*AN42 -> 0.116 | AS42: =AS41 -> 169
A44: 1 | B44: 8 | C44: ET-COVER | D44: =MID(E44,9,2) -> PT | E44: RTHTMTBNPT72X69X10 | F44: =LEFT(E44,MIN(FIND({0,1,2,3,4,5,6,7,8,9},E44&"0123456789"))-1) -> RTHTMTBNPT | G44: =SUBSTITUTE(E44,F44,"") -> 72X69X10 | H44: =IFERROR(LEFT(G44,FIND("-",G44)-1),G44) -> 72X69X10 | I44: =SEARCH("X",H44) -> 3 | J44: =SEARCH("X",H44,I44+1) -> 6 | K44: =LEFT(G44,SEARCH("x",G44)-1) -> 72 | L44: =MID(H44,I44+1,J44-I44-1) -> 69 | M44: =MID(H44,J44+1,20) -> 10 | N44: ="SFG-FRBNPK-ET-CVR-"&K44&"X"&L44&"X"&M44 -> SFG-FRBNPK-ET-CVR-72X69X10 | P44: =ROUND(((((K44+L44+K44+L44)+3)*0.0254)*5.3196),3) -> 38.509 | Q44: 0 | R44: =P44+Q44 -> 38.509 | S44: ="Restonic Hotel Motel ET Cover "&K44&"X"&L44&"X"&M44 -> Restonic Hotel Motel ET Cover 72X69X10 | T44: =N44 -> SFG-FRBNPK-ET-CVR-72X69X10 | U44: =T44=N44 -> TRUE | V44: =S44=W44 -> TRUE | W44: =S44 -> Restonic Hotel Motel ET Cover 72X69X10 | X44: Standard | Y44: Production | Z44: TAIL-ET-PT | AA44: NOS | AB44: 1 | AC44: MRP&Rollup | AD44: CBESFG | AE44: 10 | AF44: I | AG44: RM-THRD-QS-TKT40 | AH44: THREAD TKT40 210D/3 PLY 10000MTS | AI44: MTR | AJ44: =R44 -> 38.509 | AK44: CBEWIP | AL44: Backflush | AM44: Active | AN44: =AJ44/10000 -> 0.0038509 | AO44: =VLOOKUP(AG44,'RM-cost - feb-24'!B:P,15,0) -> 231.1423 | AP44: =AO44*AN44 -> 0.89010588 | AQ44: =SUM(AP44:AP48) -> 177.87541 | AR44: =ROUND(AQ44,0) -> 178 | AS44: =AR44 -> 178 | AT44: =+AS44+AY44 -> 200.02732 | AU44: =+SUM(((AS44*3%*18%))) -> 0.9612 | AV44: =+SUM(((AS44*14.33%*53%))) -> 13.518922 | AW44: =+SUM(((AS44*5.92%*53%))) -> 5.584928 | AX44: =+SUM(((AS44*2.08%*53%))) -> 1.962272 | AY44: =SUM(AU44:AX48) -> 22.027322 | AZ44: =ROUNDUP(AT44,0) -> 201 | BA44: =AZ44 -> 201
A45: 2 | B45: =B44 -> 8 | C45: =C44 -> ET-COVER | D45: =MID(E45,9,2) -> PT | E45: =E44 -> RTHTMTBNPT72X69X10 | F45: =F44 -> RTHTMTBNPT | G45: =G44 -> 72X69X10 | H45: =H44 -> 72X69X10 | I45: =I44 -> 3 | J45: =J44 -> 6 | K45: =K44 -> 72 | L45: =L44 -> 69 | M45: =M44 -> 10 | N45: ="SFG-FRBNPK-ET-CVR-"&K45&"X"&L45&"X"&M45 -> SFG-FRBNPK-ET-CVR-72X69X10 | O45: =K45*L45/144 -> 34.5 | P45: =ROUNDUP((((K45*L45/144)*0.003)),3) -> 0.104 | S45: ="Restonic Hotel Motel ET Cover "&K45&"X"&L45&"X"&M45 -> Restonic Hotel Motel ET Cover 72X69X10 | T45: =T44 -> SFG-FRBNPK-ET-CVR-72X69X10 | U45: =T45=N45 -> TRUE | V45: =S45=W45 -> TRUE | W45: =W44 -> Restonic Hotel Motel ET Cover 72X69X10 | X45: Standard | Y45: Production | Z45: TAIL-ET-PT | AA45: NOS | AB45: 1 | AC45: MRP&Rollup | AD45: CBESFG | AE45: 20 | AF45: I | AG45: RM-NWN-70GSMX6INCH | AH45: NON WOVEN FABRIC 70GSMX6" | AI45: KGS | AJ45: 0.071 | AK45: CBEWIP | AL45: Backflush | AM45: Active | AN45: =AJ45 -> 0.071 | AO45: =VLOOKUP(AG45,'RM-cost - feb-24'!B:P,15,0) -> 113.786 | AP45: =AO45*AN45 -> 8.078806 | AS45: =AS44 -> 178
A46: 3 | B46: =B45 -> 8 | C46: =C45 -> ET-COVER | D46: =MID(E46,9,2) -> PT | E46: =E45 -> RTHTMTBNPT72X69X10 | F46: =F45 -> RTHTMTBNPT | G46: =G45 -> 72X69X10 | H46: =H45 -> 72X69X10 | I46: =I45 -> 3 | J46: =J45 -> 6 | K46: =K45 -> 72 | L46: =L45 -> 69 | M46: =M45 -> 10 | N46: ="SFG-FRBNPK-ET-CVR-"&K46&"X"&L46&"X"&M46 -> SFG-FRBNPK-ET-CVR-72X69X10 | P46: =ROUNDUP((((K46*L46/144)*0.00692)),3) -> 0.239 | Q46: =P46=AJ46 -> FALSE | S46: ="Restonic Hotel Motel ET Cover "&K46&"X"&L46&"X"&M46 -> Restonic Hotel Motel ET Cover 72X69X10 | T46: =T45 -> SFG-FRBNPK-ET-CVR-72X69X10 | U46: =T46=N46 -> TRUE | V46: =S46=W46 -> TRUE | W46: =W45 -> Restonic Hotel Motel ET Cover 72X69X10 | X46: Standard | Y46: Production | Z46: TAIL-ET-PT | AA46: NOS | AB46: 1 | AC46: MRP&Rollup | AD46: CBESFG | AE46: 30 | AF46: I | AG46: RML-NWN-70GSMX76" | AH46: NON WOVEN FABRIC WHITE 70 GSM 76 INCH | AI46: KGS | AJ46: 0.238 | AK46: CBEWIP | AL46: Backflush | AM46: Active | AN46: =AJ46 -> 0.238 | AO46: =VLOOKUP(AG46,'RM-cost - feb-24'!B:P,15,0) -> 112.8872 | AP46: =AO46*AN46 -> 26.867154 | AS46: =AS45 -> 178
A47: 4 | B47: =B46 -> 8 | C47: =C46 -> ET-COVER | D47: =MID(E47,9,2) -> PT | E47: =E46 -> RTHTMTBNPT72X69X10 | F47: =F46 -> RTHTMTBNPT | G47: =G46 -> 72X69X10 | H47: =H46 -> 72X69X10 | I47: =I46 -> 3 | J47: =J46 -> 6 | K47: =K46 -> 72 | L47: =L46 -> 69 | M47: =M46 -> 10 | N47: ="SFG-FRBNPK-ET-CVR-"&K47&"X"&L47&"X"&M47 -> SFG-FRBNPK-ET-CVR-72X69X10 | P47: =ROUND(((((K47+L47+K47+L47)+3))*0.0254),3) -> 7.239 | Q47: =P47=AJ47 -> TRUE | S47: ="Restonic Hotel Motel ET Cover "&K47&"X"&L47&"X"&M47 -> Restonic Hotel Motel ET Cover 72X69X10 | T47: =T46 -> SFG-FRBNPK-ET-CVR-72X69X10 | U47: =T47=N47 -> TRUE | V47: =S47=W47 -> TRUE | W47: =W46 -> Restonic Hotel Motel ET Cover 72X69X10 | X47: Standard | Y47: Production | Z47: TAIL-ET-PT | AA47: NOS | AB47: 1 | AC47: MRP&Rollup | AD47: CBESFG | AE47: 40 | AF47: I | AG47: SFG-RTHTMT-BNPK-ETBOR-11CM | AH47: Hotel Motel Poc ET-10 & 12 8MM/16D Pre Foam Border 11 CM Height | AI47: MTR | AJ47: =P47 -> 7.239 | AK47: CBESFG | AL47: Backflush | AM47: Active | AN47: =AJ47 -> 7.239 | AO47: =VLOOKUP(AG47,'SFG-rate rm - feb-24'!A:B,2,0) -> 19.60538 | AP47: =AO47*AN47 -> 141.92335 | AS47: =AS46 -> 178
...

Sheet Item creat
A1: S.no | B1: R.no | C1: Item | D1: Item Desc | E1: PS Usage | F1: PS Category | G1: Process Plan | H1: Uom | I1: Qty | J1: Default For | K1: Wh Code | L1: Rm-cost | M1: PRO-RATE
A2: 1 | B2: 1 | C2: SFG-FRBNPK-ET-CVR-72X33X10 | D2: Restonic Hotel Motel ET Cover 72X33X10 | E2: Standard | F2: Production | G2: TAIL-ET-PT | H2: NOS | I2: 1 | J2: MRP&Rollup | K2: CBESFG | L2: 126 | M2: 142
A3: 2 | B3: 2 | C3: SFG-FRBNPK-ET-CVR-72X39X10 | D3: Restonic Hotel Motel ET Cover 72X39X10 | E3: Standard | F3: Production | G3: TAIL-ET-PT | H3: NOS | I3: 1 | J3: MRP&Rollup | K3: CBESFG | L3: 134 | M3: 151
A4: 3 | B4: 3 | C4: SFG-FRBNPK-ET-CVR-72X45X10 | D4: Restonic Hotel Motel ET Cover 72X45X10 | E4: Standard | F4: Production | G4: TAIL-ET-PT | H4: NOS | I4: 1 | J4: MRP&Rollup | K4: CBESFG | L4: 143 | M4: 161
A5: 4 | B5: 4 | C5: SFG-FRBNPK-ET-CVR-72X51X10 | D5: Restonic Hotel Motel ET Cover 72X51X10 | E5: Standard | F5: Production | G5: TAIL-ET-PT | H5: NOS | I5: 1 | J5: MRP&Rollup | K5: CBESFG | L5: 151 | M5: 170
A6: 5 | B6: 5 | C6: SFG-FRBNPK-ET-CVR-72X54X10 | D6: Restonic Hotel Motel ET Cover 72X54X10 | E6: Standard | F6: Production | G6: TAIL-ET-PT | H6: NOS | I6: 1 | J6: MRP&Rollup | K6: CBESFG | L6: 156 | M6: 176
A7: 6 | B7: 6 | C7: SFG-FRBNPK-ET-CVR-72X57X10 | D7: Restonic Hotel Motel ET Cover 72X57X10 | E7: Standard | F7: Production | G7: TAIL-ET-PT | H7: NOS | I7: 1 | J7: MRP&Rollup | K7: CBESFG | L7: 160 | M7: 180
A8: 7 | B8: 7 | C8: SFG-FRBNPK-ET-CVR-72X63X10 | D8: Restonic Hotel Motel ET Cover 72X63X10 | E8: Standard | F8: Production | G8: TAIL-ET-PT | H8: NOS | I8: 1 | J8: MRP&Rollup | K8: CBESFG | L8: 169 | M8: 190
A9: 8 | B9: 8 | C9: SFG-FRBNPK-ET-CVR-72X69X10 | D9: Restonic Hotel Motel ET Cover 72X69X10 | E9: Standard | F9: Production | G9: TAIL-ET-PT | H9: NOS | I9: 1 | J9: MRP&Rollup | K9: CBESFG | L9: 178 | M9: 201
A10: 9 | B10: 9 | C10: SFG-FRBNPK-ET-CVR-75X33X10 | D10: Restonic Hotel Motel ET Cover 75X33X10 | E10: Standard | F10: Production | G10: TAIL-ET-PT | H10: NOS | I10: 1 | J10: MRP&Rollup | K10: CBESFG | L10: 129 | M10: 145
A11: 10 | B11: 10 | C11: SFG-FRBNPK-ET-CVR-75X39X10 | D11: Restonic Hotel Motel ET Cover 75X39X10 | E11: Standard | F11: Production | G11: TAIL-ET-PT | H11: NOS | I11: 1 | J11: MRP&Rollup | K11: CBESFG | L11: 137 | M11: 154
A12: 11 | B12: 11 | C12: SFG-FRBNPK-ET-CVR-75X45X10 | D12: Restonic Hotel Motel ET Cover 75X45X10 | E12: Standard | F12: Production | G12: TAIL-ET-PT | H12: NOS | I12: 1 | J12: MRP&Rollup | K12: CBESFG | L12: 146 | M12: 165
A13: 12 | B13: 12 | C13: SFG-FRBNPK-ET-CVR-75X51X10 | D13: Restonic Hotel Motel ET Cover 75X51X10 | E13: Standard | F13: Production | G13: TAIL-ET-PT | H13: NOS | I13: 1 | J13: MRP&Rollup | K13: CBESFG | L13: 155 | M13: 175
... A41: 40 | B41: 40 | C41: SFG-FRBNPK-ET-CVR-84X69X10 | D41: Restonic Hotel Motel ET Cover 84X69X10 | E41: Standard | F41: Production | G41: TAIL-ET-PT | H41: NOS | I41: 1 | J41: MRP&Rollup | K41: CBESFG | L41: 198 | M41: 223

Sheet ps creat & upload
A1: S.no | B1: R.no | C1: Bom Code/PS.No | D1: PS Desc. | E1: Item | F1: Item Desc | G1: PS Usage | H1: PS Category | I1: Process Plan | J1: Uom | K1: Qty | L1: Default For | M1: Wh Code | N1: PS Seq | O1: I/O Flag | P1: Issue Item | Q1: Item Desc | R1: Uom | S1: Qty | T1: Std Wh Code | U1: Backflush | V1: Status
A2: 1 | B2: 1 | C2: SFG-FRBNPK-ET-CVR-72X33X10 | D2: Restonic Hotel Motel ET Cover 72X33X10 | E2: SFG-FRBNPK-ET-CVR-72X33X10 | F2: Restonic Hotel Motel ET Cover 72X33X10 | G2: Standard | H2: Production | I2: TAIL-ET-PT | J2: NOS | K2: 1 | L2: MRP&Rollup | M2: CBESFG | N2: 10 | O2: I | P2: RM-THRD-QS-TKT40 | Q2: THREAD TKT40 210D/3 PLY 10000MTS | R2: MTR | S2: 28.78 | T2: CBEWIP | U2: Backflush | V2: Active
A3: 2 | B3: 1 | C3: SFG-FRBNPK-ET-CVR-72X33X10 | D3: Restonic Hotel Motel ET Cover 72X33X10 | E3: SFG-FRBNPK-ET-CVR-72X33X10 | F3: Restonic Hotel Motel ET Cover 72X33X10 | G3: Standard | H3: Production | I3: TAIL-ET-PT | J3: NOS | K3: 1 | L3: MRP&Rollup | M3: CBESFG | N3: 20 | O3: I | P3: RM-NWN-70GSMX6INCH | Q3: NON WOVEN FABRIC 70GSMX6" | R3: KGS | S3: 0.052 | T3: CBEWIP | U3: Backflush | V3: Active
A4: 3 | B4: 1 | C4: SFG-FRBNPK-ET-CVR-72X33X10 | D4: Restonic Hotel Motel ET Cover 72X33X10 | E4: SFG-FRBNPK-ET-CVR-72X33X10 | F4: Restonic Hotel Motel ET Cover 72X33X10 | G4: Standard | H4: Production | I4: TAIL-ET-PT | J4: NOS | K4: 1 | L4: MRP&Rollup | M4: CBESFG | N4: 30 | O4: I | P4: RML-NWN-70GSMX76" | Q4: NON WOVEN FABRIC WHITE 70 GSM 76 INCH | R4: KGS | S4: 0.113 | T4: CBEWIP | U4: Backflush | V4: Active
A5: 4 | B5: 1 | C5: SFG-FRBNPK-ET-CVR-72X33X10 | D5: Restonic Hotel Motel ET Cover 72X33X10 | E5: SFG-FRBNPK-ET-CVR-72X33X10 | F5: Restonic Hotel Motel ET Cover 72X33X10 | G5: Standard | H5: Production | I5: TAIL-ET-PT | J5: NOS | K5: 1 | L5: MRP&Rollup | M5: CBESFG | N5: 40 | O5: I | P5: SFG-RTHTMT-BNPK-ETBOR-11CM | Q5: Hotel Motel Poc ET-10 & 12 8MM/16D Pre Foam Border 11 CM Height | R5: MTR | S5: 5.41 | T5: CBESFG | U5: Backflush | V5: Active
A6: 5 | B6: 1 | C6: SFG-FRBNPK-ET-CVR-72X33X10 | D6: Restonic Hotel Motel ET Cover 72X33X10 | E6: SFG-FRBNPK-ET-CVR-72X33X10 | F6: Restonic Hotel Motel ET Cover 72X33X10 | G6: Standard | H6: Production | I6: TAIL-ET-PT | J6: NOS | K6: 1 | L6: MRP&Rollup | M6: CBESFG | N6: 50 | O6: I | P6: HW-CTON-THREAD | Q6: COTTON THREAD WHITE 3PLY | R6: MTR | S6: 10 | T6: CBEWIP | U6: Backflush | V6: Active
A7: 6 | B7: 2 | C7: SFG-FRBNPK-ET-CVR-72X39X10 | D7: Restonic Hotel Motel ET Cover 72X39X10 | E7: SFG-FRBNPK-ET-CVR-72X39X10 | F7: Restonic Hotel Motel ET Cover 72X39X10 | G7: Standard | H7: Production | I7: TAIL-ET-PT | J7: NOS | K7: 1 | L7: MRP&Rollup | M7: CBESFG | N7: 10 | O7: I | P7: RM-THRD-QS-TKT40 | Q7: THREAD TKT40 210D/3 PLY 10000MTS | R7: MTR | S7: 30.402 | T7: CBEWIP | U7: Backflush | V7: Active
A8: 7 | B8: 2 | C8: SFG-FRBNPK-ET-CVR-72X39X10 | D8: Restonic Hotel Motel ET Cover 72X39X10 | E8: SFG-FRBNPK-ET-CVR-72X39X10 | F8: Restonic Hotel Motel ET Cover 72X39X10 | G8: Standard | H8: Production | I8: TAIL-ET-PT | J8: NOS | K8: 1 | L8: MRP&Rollup | M8: CBESFG | N8: 20 | O8: I | P8: RM-NWN-70GSMX6INCH | Q8: NON WOVEN FABRIC 70GSMX6" | R8: KGS | S8: 0.056 | T8: CBEWIP | U8: Backflush | V8: Active
A9: 8 | B9: 2 | C9: SFG-FRBNPK-ET-CVR-72X39X10 | D9: Restonic Hotel Motel ET Cover 72X39X10 | E9: SFG-FRBNPK-ET-CVR-72X39X10 | F9: Restonic Hotel Motel ET Cover 72X39X10 | G9: Standard | H9: Production | I9: TAIL-ET-PT | J9: NOS | K9: 1 | L9: MRP&Rollup | M9: CBESFG | N9: 30 | O9: I | P9: RML-NWN-70GSMX76" | Q9: NON WOVEN FABRIC WHITE 70 GSM 76 INCH | R9: KGS | S9: 0.133 | T9: CBEWIP | U9: Backflush | V9: Active
A10: 9 | B10: 2 | C10: SFG-FRBNPK-ET-CVR-72X39X10 | D10: Restonic Hotel Motel ET Cover 72X39X10 | E10: SFG-FRBNPK-ET-CVR-72X39X10 | F10: Restonic Hotel Motel ET Cover 72X39X10 | G10: Standard | H10: Production | I10: TAIL-ET-PT | J10: NOS | K10: 1 | L10: MRP&Rollup | M10: CBESFG | N10: 40 | O10: I | P10: SFG-RTHTMT-BNPK-ETBOR-11CM | Q10: Hotel Motel Poc ET-10 & 12 8MM/16D Pre Foam Border 11 CM Height | R10: MTR | S10: 5.715 | T10: CBESFG | U10: Backflush | V10: Active
A11: 10 | B11: 2 | C11: SFG-FRBNPK-ET-CVR-72X39X10 | D11: Restonic Hotel Motel ET Cover 72X39X10 | E11: SFG-FRBNPK-ET-CVR-72X39X10 | F11: Restonic Hotel Motel ET Cover 72X39X10 | G11: Standard | H11: Production | I11: TAIL-ET-PT | J11: NOS | K11: 1 | L11: MRP&Rollup | M11: CBESFG | N11: 50 | O11: I | P11: HW-CTON-THREAD | Q11: COTTON THREAD WHITE 3PLY | R11: MTR | S11: 10 | T11: CBEWIP | U11: Backflush | V11: Active
A12: 11 | B12: 3 | C12: SFG-FRBNPK-ET-CVR-72X45X10 | D12: Restonic Hotel Motel ET Cover 72X45X10 | E12: SFG-FRBNPK-ET-CVR-72X45X10 | F12: Restonic Hotel Motel ET Cover 72X45X10 | G12: Standard | H12: Production | I12: TAIL-ET-PT | J12: NOS | K12: 1 | L12: MRP&Rollup | M12: CBESFG | N12: 10 | O12: I | P12: RM-THRD-QS-TKT40 | Q12: THREAD TKT40 210D/3 PLY 10000MTS | R12: MTR | S12: 32.023 | T12: CBEWIP | U12: Backflush | V12: Active
A13: 12 | B13: 3 | C13: SFG-FRBNPK-ET-CVR-72X45X10 | D13: Restonic Hotel Motel ET Cover 72X45X10 | E13: SFG-FRBNPK-ET-CVR-72X45X10 | F13: Restonic Hotel Motel ET Cover 72X45X10 | G13: Standard | H13: Production | I13: TAIL-ET-PT | J13: NOS | K13: 1 | L13: MRP&Rollup | M13: CBESFG | N13: 20 | O13: I | P13: RM-NWN-70GSMX6INCH | Q13: NON WOVEN FABRIC 70GSMX6" | R13: KGS | S13: 0.058 | T13: CBEWIP | U13: Backflush | V13: Active
... A201: 200 | B201: 40 | C201: SFG-FRBNPK-ET-CVR-84X69X10 | D201: Restonic Hotel Motel ET Cover 84X69X10 | E201: SFG-FRBNPK-ET-CVR-84X69X10 | F201: Restonic Hotel Motel ET Cover 84X69X10 | G201: Standard | H201: Production | I201: TAIL-ET-PT | J201: NOS | K201: 1 | L201: MRP&Rollup | M201: CBESFG | N201: 50 | O201: I | P201: HW-CTON-THREAD | Q201: COTTON THREAD WHITE 3PLY | R201: MTR | S201: 10 | T201: CBEWIP | U201: Backflush | V201: Active

Sheet RM-cost - feb-24
A1: SI.No | B1: Item Code | C1: Item Desc | D1: UOM | E1: Warehouse | F1: Opening Stock Qty | G1: Opening Stock Rate | H1: Opening Stock Value | I1: Stock In Qty | J1: Stock In Rate | K1: Stock In Value | L1: Stock Out Qty | M1: Stock Out Rate | N1: Stock Out Value | O1: Closing Stock Qty | P1: Closing Stock Rate | Q1: Closing Stock Value | R1: Item Account Group | S1: Item Account Group Desc | T1: Item Category
A2: 33 | B2: RML-CS-RTC-PLUSH-7.5 | C2: CORNER SHOES RESTONIC PLUSH - 7.5" | D2: NOS | E2: CBERM | F2: 900 | G2: 10.2033 | H2: 9182.97 | I2: 600 | J2: 10 | K2: 6000 | L2: 300 | M2: 10.1452 | N2: 3043.57 | O2: 1200 | P2: 10.1162 | Q2: 12139.4 | R2: LCE | S2: Label,CnrShoe,CentreBand,EdgeTape-10195 | T2: MATRESS
A3: 35 | B3: RML-CS-RTC-PLUSH-9.5 | C3: CORNER SHOES RESTONIC PLUSH - 9.5" | D3: NOS | E3: CBERM | F3: 1000 | G3: 10.3332 | H3: 10333.16 | I3: 500 | J3: 12.3 | K3: 6150 | L3: 200 | M3: 10.9888 | N3: 2197.76 | O3: 1300 | P3: 10.9888 | Q3: 14285.4 | R3: LCE | S3: Label,CnrShoe,CentreBand,EdgeTape-10195 | T3: MATRESS
A4: 37 | B4: RML-CS-SPG-6.5" | C4: CORNER SHOES. SPINE GUARD - 6.5" | D4: NOS | E4: CBERM | F4: 1200 | G4: 10.7018 | H4: 12842.19 | I4: 0 | K4: 0 | L4: 200 | M4: 10.7018 | N4: 2140.36 | O4: 1000 | P4: 10.7018 | Q4: 10701.83 | R4: LCE | S4: Label,CnrShoe,CentreBand,EdgeTape-10195 | T4: MATRESS
